Workbook
Name mycementtable: 'Cement Portfolio'!$B$1:$CI$79

Sheet Price Record
B1: Column1 | C1: Column2 | F1: Column6 | G1: Column8 | H1: Column11 | I1: Column16 | J1: Column17
K3: HMT | M3: IHT
A4: Match | B4: نام | C4: نماد | F4: دیروز | G4: آخرین معامله - مقدار | H4: قیمت پایانی - مقدار | I4: EPS | J4: P/E | K4: Market Cap | L4: Shares Hold | M4: Portfolio-AA | O4: MC -- | P4: MC ++ | Q4: Mcap Diff % | R4: Portfolio Diff % | S4: PP ++ | T4: PP -- | V4: دیروز | W4: آخرین معامله | X4: قیمت پایانی | Y4: EPS | Z4: P/E | AA4: Market Cap | AB4: Shares Hold | AC4: Portfolio-AA
A6: =IFERROR(MATCH(C6,'دیده بان بازار'!$A$5:$A$3994,0 )+4,"Closed") -> 1934 | B6: بين المللي ساروج بوشهر | C6: ساروج | D6: C | F6: =IFERROR(_xlfn.LET(_xlpm.lookup_result,_xlfn.XLOOKUP($C6,'دیده بان بازار'!$A$5:$A$3994,'دیده بان بازار'!F$5:F$3994),IF(ISERROR(_xlpm.lookup_result),V6,_xlpm.lookup_result)),V6) -> 55530 | G6: =IFERROR(_xlfn.LET(_xlpm.lookup_result,_xlfn.XLOOKUP($C6,'دیده بان بازار'!$A$5:$A$3994,'دیده بان بازار'!H$5:H$3994),IF(ISERROR(_xlpm.lookup_result),W6,_xlpm.lookup_result)),W6) -> 57190 | H6: =IFERROR(_xlfn.LET(_xlpm.lookup_result,_xlfn.XLOOKUP($C6,'دیده بان بازار'!$A$5:$A$3994,'دیده بان بازار'!K$5:K$3994),IF(ISERROR(_xlpm.lookup_result),X6,_xlpm.lookup_result)),X6) -> 57170 | I6: =IFERROR(_xlfn.LET(_xlpm.lookup_result,_xlfn.XLOOKUP($C6,'دیده بان بازار'!$A$5:$A$3994,'دیده بان بازار'!P$5:P$3994),IF(ISERROR(_xlpm.lookup_result),Y6,_xlpm.lookup_result)),Y6) -> 11890 | J6: =IFERROR(_xlfn.LET(_xlpm.lookup_result,_xlfn.XLOOKUP($C6,'دیده بان بازار'!$A$5:$A$3994,'دیده بان بازار'!Q$5:Q$3994),IF(ISERROR(_xlpm.lookup_result),Z6,_xlpm.lookup_result)),Z6) -> 4.81 | K6: =_xlfn.XLOOKUP(C6,Cement!$Q$7:$Q$35,Cement!$S$7:$S$35,"")/1000 -> 7.66346 | L6: =_xlfn.XLOOKUP(C6,'Cement Portfolio'!$O$8:$O$36,'Cement Portfolio'!$AP$8:$AP$36,"") -> 280000 | M6: =_xlfn.XLOOKUP(C6,'Cement Portfolio'!$O$8:$O$36,'Cement Portfolio'!$AQ$8:$AQ$36,"") -> 1587228.4 | O6: =IF(AND(Q6<0,R6<0,Q6<R6),Q6-R6,"") | P6: =IF(AND(Q6>=0,R6>=0,Q6>R6),Q6-R6,"") | Q6: =IFERROR(((K6-AA6)*100)/ABS($K$106),"") -> 0.081787075 | R6: =IFERROR((($AB6*$G6*0.9912*0.0001)-AC6)*100/ABS($AC$108),"") -> 2.8519501 | S6: =IF(AND(R6>0,Q6>0,R6>Q6),R6-Q6,"") -> 2.770163 | T6: =IF(AND(R6<0,Q6<0,R6<Q6),R6-Q6,"") | V6: 54640 | W6: 56100 | X6: 55530 | Y6: 11890 | Z6: 4.67 | AA6: 7.5174 | AB6: 280000 | AC6: 1556977
A7: =IFERROR(MATCH(C7,'دیده بان بازار'!$A$5:$A$3994,0 )+4,"Closed") -> 517 | B7: سيمان‌ شرق‌ | C7: سشرق | D7: C | F7: =IFERROR(_xlfn.LET(_xlpm.lookup_result,_xlfn.XLOOKUP($C7,'دیده بان بازار'!$A$5:$A$3994,'دیده بان بازار'!F$5:F$3994),IF(ISERROR(_xlpm.lookup_result),V7,_xlpm.lookup_result)),V7) -> 19150 | G7: =IFERROR(_xlfn.LET(_xlpm.lookup_result,_xlfn.XLOOKUP($C7,'دیده بان بازار'!$A$5:$A$3994,'دیده بان بازار'!H$5:H$3994),IF(ISERROR(_xlpm.lookup_result),W7,_xlpm.lookup_result)),W7) -> 19720 | H7: =IFERROR(_xlfn.LET(_xlpm.lookup_result,_xlfn.XLOOKUP($C7,'دیده بان بازار'!$A$5:$A$3994,'دیده بان بازار'!K$5:K$3994),IF(ISERROR(_xlpm.lookup_result),X7,_xlpm.lookup_result)),X7) -> 19720 | I7: =IFERROR(_xlfn.LET(_xlpm.lookup_result,_xlfn.XLOOKUP($C7,'دیده بان بازار'!$A$5:$A$3994,'دیده بان بازار'!P$5:P$3994),IF(ISERROR(_xlpm.lookup_result),Y7,_xlpm.lookup_result)),Y7) -> 3056 | J7: =IFERROR(_xlfn.LET(_xlpm.lookup_result,_xlfn.XLOOKUP($C7,'دیده بان بازار'!$A$5:$A$3994,'دیده بان بازار'!Q$5:Q$3994),IF(ISERROR(_xlpm.lookup_result),Z7,_xlpm.lookup_result)),Z7) -> 6.45 | K7: =_xlfn.XLOOKUP(C7,Cement!$Q$7:$Q$35,Cement!$S$7:$S$35,"")/1000 -> 12.2264 | L7: =_xlfn.XLOOKUP(C7,'Cement Portfolio'!$O$8:$O$36,'Cement Portfolio'!$AP$8:$AP$36,"") -> 100000 | M7: =_xlfn.XLOOKUP(C7,'Cement Portfolio'!$O$8:$O$36,'Cement Portfolio'!$AQ$8:$AQ$36,"") -> 195464.64 | O7: =IF(AND(Q7<0,R7<0,Q7<R7),Q7-R7,"") | P7: =IF(AND(Q7>=0,R7>=0,Q7>R7),Q7-R7,"") | Q7: =IFERROR(((K7-AA7)*100)/ABS($K$106),"") -> 0.18747304 | R7: =IFERROR((($AB7*$G7*0.9912*0.0001)-AC7)*100/ABS($AC$108),"") -> 1.5138136 | S7: =IF(AND(R7>0,Q7>0,R7>Q7),R7-Q7,"") -> 1.3263406 | T7: =IF(AND(R7<0,Q7<0,R7<Q7),R7-Q7,"") | V7: 18630 | W7: 19180 | X7: 19150 | Y7: 3056 | Z7: 6.27 | AA7: 11.8916 | AB7: 300000 | AC7: 570336.48
A8: =IFERROR(MATCH(C8,'دیده بان بازار'!$A$5:$A$3994,0 )+4,"Closed") -> 167 | B8: سيمان‌خاش‌ | C8: سخاش | D8: C | F8: =IFERROR(_xlfn.LET(_xlpm.lookup_result,_xlfn.XLOOKUP($C8,'دیده بان بازار'!$A$5:$A$3994,'دیده بان بازار'!F$5:F$3994),IF(ISERROR(_xlpm.lookup_result),V8,_xlpm.lookup_result)),V8) -> 11230 | G8: =IFERROR(_xlfn.LET(_xlpm.lookup_result,_xlfn.XLOOKUP($C8,'دیده بان بازار'!$A$5:$A$3994,'دیده بان بازار'!H$5:H$3994),IF(ISERROR(_xlpm.lookup_result),W8,_xlpm.lookup_result)),W8) -> 11560 | H8: =IFERROR(_xlfn.LET(_xlpm.lookup_result,_xlfn.XLOOKUP($C8,'دیده بان بازار'!$A$5:$A$3994,'دیده بان بازار'!K$5:K$3994),IF(ISERROR(_xlpm.lookup_result),X8,_xlpm.lookup_result)),X8) -> 11520 | I8: =IFERROR(_xlfn.LET(_xlpm.lookup_result,_xlfn.XLOOKUP($C8,'دیده بان بازار'!$A$5:$A$3994,'دیده بان بازار'!P$5:P$3994),IF(ISERROR(_xlpm.lookup_result),Y8,_xlpm.lookup_result)),Y8) -> 1929 | J8: =IFERROR(_xlfn.LET(_xlpm.lookup_result,_xlfn.XLOOKUP($C8,'دیده بان بازار'!$A$5:$A$3994,'دیده بان بازار'!Q$5:Q$3994),IF(ISERROR(_xlpm.lookup_result),Z8,_xlpm.lookup_result)),Z8) -> 5.97 | K8: =_xlfn.XLOOKUP(C8,Cement!$Q$7:$Q$35,Cement!$S$7:$S$35,"")/1000 -> 6.1268 | L8: =_xlfn.XLOOKUP(C8,'Cement Portfolio'!$O$8:$O$36,'Cement Portfolio'!$AP$8:$AP$36,"") -> 2650000 | M8: =_xlfn.XLOOKUP(C8,'Cement Portfolio'!$O$8:$O$36,'Cement Portfolio'!$AQ$8:$AQ$36,"") -> 3036442.1 | O8: =IF(AND(Q8<0,R8<0,Q8<R8),Q8-R8,"") | P8: =IF(AND(Q8>=0,R8>=0,Q8>R8),Q8-R8,"") | Q8: =IFERROR(((K8-AA8)*100)/ABS($K$106),"") -> 0.089032896 | R8: =IFERROR((($AB8*$G8*0.9912*0.0001)-AC8)*100/ABS($AC$108),"") -> 7.4289002 | S8: =IF(AND(R8>0,Q8>0,R8>Q8),R8-Q8,"") -> 7.3398673 | T8: =IF(AND(R8<0,Q8<0,R8<Q8),R8-Q8,"") | V8: 10960 | W8: 11260 | X8: 11230 | Y8: 1929 | Z8: 5.82 | AA8: 5.9678 | AB8: 2650000 | AC8: 2957641.7
A9: =IFERROR(MATCH(C9,'دیده بان بازار'!$A$5:$A$3994,0 )+4,"Closed") -> 1362 | B9: سيمان‌ بهبهان‌ | C9: سبهان | D9: C | F9: =IFERROR(_xlfn.LET(_xlpm.lookup_result,_xlfn.XLOOKUP($C9,'دیده بان بازار'!$A$5:$A$3994,'دیده بان بازار'!F$5:F$3994),IF(ISERROR(_xlpm.lookup_result),V9,_xlpm.lookup_result)),V9) -> 5310 | G9: =IFERROR(_xlfn.LET(_xlpm.lookup_result,_xlfn.XLOOKUP($C9,'دیده بان بازار'!$A$5:$A$3994,'دیده بان بازار'!H$5:H$3994),IF(ISERROR(_xlpm.lookup_result),W9,_xlpm.lookup_result)),W9) -> 5460 | H9: =IFERROR(_xlfn.LET(_xlpm.lookup_result,_xlfn.XLOOKUP($C9,'دیده بان بازار'!$A$5:$A$3994,'دیده بان بازار'!K$5:K$3994),IF(ISERROR(_xlpm.lookup_result),X9,_xlpm.lookup_result)),X9) -> 5460 | I9: =IFERROR(_xlfn.LET(_xlpm.lookup_result,_xlfn.XLOOKUP($C9,'دیده بان بازار'!$A$5:$A$3994,'دیده بان بازار'!P$5:P$3994),IF(ISERROR(_xlpm.lookup_result),Y9,_xlpm.lookup_result)),Y9) -> 989 | J9: =IFERROR(_xlfn.LET(_xlpm.lookup_result,_xlfn.XLOOKUP($C9,'دیده بان بازار'!$A$5:$A$3994,'دیده بان بازار'!Q$5:Q$3994),IF(ISERROR(_xlpm.lookup_result),Z9,_xlpm.lookup_result)),Z9) -> 5.52 | K9: =_xlfn.XLOOKUP(C9,Cement!$Q$7:$Q$35,Cement!$S$7:$S$35,"")/1000 -> 4.0404 | L9: =_xlfn.XLOOKUP(C9,'Cement Portfolio'!$O$8:$O$36,'Cement Portfolio'!$AP$8:$AP$36,"") -> 2400000 | M9: =_xlfn.XLOOKUP(C9,'Cement Portfolio'!$O$8:$O$36,'Cement Portfolio'!$AQ$8:$AQ$36,"") -> 1298868.5 | O9: =IF(AND(Q9<0,R9<0,Q9<R9),Q9-R9,"") | P9: =IF(AND(Q9>=0,R9>=0,Q9>R9),Q9-R9,"") | Q9: =IFERROR(((K9-AA9)*100)/ABS($K$106),"") -> 0.058011372 | R9: =IFERROR((($AB9*$G9*0.9912*0.0001)-AC9)*100/ABS($AC$108),"") -> 3.1397616 | S9: =IF(AND(R9>0,Q9>0,R9>Q9),R9-Q9,"") -> 3.0817502 | T9: =IF(AND(R9<0,Q9<0,R9<Q9),R9-Q9,"") | V9: 5170 | W9: 5320 | X9: 5310 | Y9: 989 | Z9: 5.37 | AA9: 3.9368 | AB9: 2400000 | AC9: 1265564.2
A10: =IFERROR(MATCH(C10,'دیده بان بازار'!$A$5:$A$3994,0 )+4,"Closed") -> 1658 | B10: سيمان‌ سپاهان‌ | C10: سپاها | D10: C | F10: =IFERROR(_xlfn.LET(_xlpm.lookup_result,_xlfn.XLOOKUP($C10,'دیده بان بازار'!$A$5:$A$3994,'دیده بان بازار'!F$5:F$3994),IF(ISERROR(_xlpm.lookup_result),V10,_xlpm.lookup_result)),V10) -> 18740 | G10: =IFERROR(_xlfn.LET(_xlpm.lookup_result,_xlfn.XLOOKUP($C10,'دیده بان بازار'!$A$5:$A$3994,'دیده بان بازار'!H$5:H$3994),IF(ISERROR(_xlpm.lookup_result),W10,_xlpm.lookup_result)),W10) -> 19300 | H10: =IFERROR(_xlfn.LET(_xlpm.lookup_result,_xlfn.XLOOKUP($C10,'دیده بان بازار'!$A$5:$A$3994,'دیده بان بازار'!K$5:K$3994),IF(ISERROR(_xlpm.lookup_result),X10,_xlpm.lookup_result)),X10) -> 19290 | I10: =IFERROR(_xlfn.LET(_xlpm.lookup_result,_xlfn.XLOOKUP($C10,'دیده بان بازار'!$A$5:$A$3994,'دیده بان بازار'!P$5:P$3994),IF(ISERROR(_xlpm.lookup_result),Y10,_xlpm.lookup_result)),Y10) -> 2433 | J10: =IFERROR(_xlfn.LET(_xlpm.lookup_result,_xlfn.XLOOKUP($C10,'دیده بان بازار'!$A$5:$A$3994,'دیده بان بازار'!Q$5:Q$3994),IF(ISERROR(_xlpm.lookup_result),Z10,_xlpm.lookup_result)),Z10) -> 7.93 | K10: =_xlfn.XLOOKUP(C10,Cement!$Q$7:$Q$35,Cement!$S$7:$S$35,"")/1000 -> 13.0275 | L10: =_xlfn.XLOOKUP(C10,'Cement Portfolio'!$O$8:$O$36,'Cement Portfolio'!$AP$8:$AP$36,"") -> 0 | M10: =_xlfn.XLOOKUP(C10,'Cement Portfolio'!$O$8:$O$36,'Cement Portfolio'!$AQ$8:$AQ$36,"") -> 0 | O10: =IF(AND(Q10<0,R10<0,Q10<R10),Q10-R10,"") | P10: =IF(AND(Q10>=0,R10>=0,Q10>R10),Q10-R10,"") -> 0.20410372 | Q10: =IFERROR(((K10-AA10)*100)/ABS($K$106),"") -> 0.20410372 | R10: =IFERROR((($AB10*$G10*0.9912*0.0001)-AC10)*100/ABS($AC$108),"") -> 0 | S10: =IF(AND(R10>0,Q10>0,R10>Q10),R10-Q10,"") | T10: =IF(AND(R10<0,Q10<0,R10<Q10),R10-Q10,"") | V10: 18220 | W10: 18760 | X10: 18740 | Y10: 2433 | Z10: 7.7 | AA10: 12.663 | AB10: 0 | AC10: 0
A11: =IFERROR(MATCH(C11,'دیده بان بازار'!$A$5:$A$3994,0 )+4,"Closed") -> 1754 | B11: سيمان‌ شاهرود | C11: سرود | D11: C | F11: =IFERROR(_xlfn.LET(_xlpm.lookup_result,_xlfn.XLOOKUP($C11,'دیده بان بازار'!$A$5:$A$3994,'دیده بان بازار'!F$5:F$3994),IF(ISERROR(_xlpm.lookup_result),V11,_xlpm.lookup_result)),V11) -> 16180 | G11: =IFERROR(_xlfn.LET(_xlpm.lookup_result,_xlfn.XLOOKUP($C11,'دیده بان بازار'!$A$5:$A$3994,'دیده بان بازار'!H$5:H$3994),IF(ISERROR(_xlpm.lookup_result),W11,_xlpm.lookup_result)),W11) -> 16660 | H11: =IFERROR(_xlfn.LET(_xlpm.lookup_result,_xlfn.XLOOKUP($C11,'دیده بان بازار'!$A$5:$A$3994,'دیده بان بازار'!K$5:K$3994),IF(ISERROR(_xlpm.lookup_result),X11,_xlpm.lookup_result)),X11) -> 16660 | I11: =IFERROR(_xlfn.LET(_xlpm.lookup_result,_xlfn.XLOOKUP($C11,'دیده بان بازار'!$A$5:$A$3994,'دیده بان بازار'!P$5:P$3994),IF(ISERROR(_xlpm.lookup_result),Y11,_xlpm.lookup_result)),Y11) -> 2424 | J11: =IFERROR(_xlfn.LET(_xlpm.lookup_result,_xlfn.XLOOKUP($C11,'دیده بان بازار'!$A$5:$A$3994,'دیده بان بازار'!Q$5:Q$3994),IF(ISERROR(_xlpm.lookup_result),Z11,_xlpm.lookup_result)),Z11) -> 6.87 | K11: =_xlfn.XLOOKUP(C11,Cement!$Q$7:$Q$35,Cement!$S$7:$S$35,"")/1000 -> 15.993698 | L11: =_xlfn.XLOOKUP(C11,'Cement Portfolio'!$O$8:$O$36,'Cement Portfolio'!$AP$8:$AP$36,"") -> 1000000 | M11: =_xlfn.XLOOKUP(C11,'Cement Portfolio'!$O$8:$O$36,'Cement Portfolio'!$AQ$8:$AQ$36,"") -> 1651339.2 | O11: =IF(AND(Q11<0,R11<0,Q11<R11),Q11-R11,"") | P11: =IF(AND(Q11>=0,R11>=0,Q11>R11),Q11-R11,"") | Q11: =IFERROR(((K11-AA11)*100)/ABS($K$106),"") -> 0.258029 | R11: =IFERROR((($AB11*$G11*0.9912*0.0001)-AC11)*100/ABS($AC$108),"") -> 4.4853737 | S11: =IF(AND(R11>0,Q11>0,R11>Q11),R11-Q11,"") -> 4.2273447 | T11: =IF(AND(R11<0,Q11<0,R11<Q11),R11-Q11,"") | V11: 15710 | W11: 16180 | X11: 16180 | Y11: 2424 | Z11: 6.67 | AA11: 15.532895 | AB11: 1000000 | AC11: 1603761.6
A12: =IFERROR(MATCH(C12,'دیده بان بازار'!$A$5:$A$3994,0 )+4,"Closed") -> 648 | B12: سيمان خوزستان | C12: سخوز | D12: C | F12: =IFERROR(_xlfn.LET(_xlpm.lookup_result,_xlfn.XLOOKUP($C12,'دیده بان بازار'!$A$5:$A$3994,'دیده بان بازار'!F$5:F$3994),IF(ISERROR(_xlpm.lookup_result),V12,_xlpm.lookup_result)),V12) -> 71630 | G12: =IFERROR(_xlfn.LET(_xlpm.lookup_result,_xlfn.XLOOKUP($C12,'دیده بان بازار'!$A$5:$A$3994,'دیده بان بازار'!H$5:H$3994),IF(ISERROR(_xlpm.lookup_result),W12,_xlpm.lookup_result)),W12) -> 73770 | H12: =IFERROR(_xlfn.LET(_xlpm.lookup_result,_xlfn.XLOOKUP($C12,'دیده بان بازار'!$A$5:$A$3994,'دیده بان بازار'!K$5:K$3994),IF(ISERROR(_xlpm.lookup_result),X12,_xlpm.lookup_result)),X12) -> 73770 | I12: =IFERROR(_xlfn.LET(_xlpm.lookup_result,_xlfn.XLOOKUP($C12,'دیده بان بازار'!$A$5:$A$3994,'دیده بان بازار'!P$5:P$3994),IF(ISERROR(_xlpm.lookup_result),Y12,_xlpm.lookup_result)),Y12) -> 15662 | J12: =IFERROR(_xlfn.LET(_xlpm.lookup_result,_xlfn.XLOOKUP($C12,'دیده بان بازار'!$A$5:$A$3994,'دیده بان بازار'!Q$5:Q$3994),IF(ISERROR(_xlpm.lookup_result),Z12,_xlpm.lookup_result)),Z12) -> 4.71 | K12: =_xlfn.XLOOKUP(C12,Cement!$Q$7:$Q$35,Cement!$S$7:$S$35,"")/1000 -> 10.3278 | L12: =_xlfn.XLOOKUP(C12,'Cement Portfolio'!$O$8:$O$36,'Cement Portfolio'!$AP$8:$AP$36,"") -> 0 | M12: =_xlfn.XLOOKUP(C12,'Cement Portfolio'!$O$8:$O$36,'Cement Portfolio'!$AQ$8:$AQ$36,"") -> 0 | O12: =IF(AND(Q12<0,R12<0,Q12<R12),Q12-R12,"") | P12: =IF(AND(Q12>=0,R12>=0,Q12>R12),Q12-R12,"") -> 0.16776261 | Q12: =IFERROR(((K12-AA12)*100)/ABS($K$106),"") -> 0.16776261 | R12: =IFERROR((($AB12*$G12*0.9912*0.0001)-AC12)*100/ABS($AC$108),"") -> 0 | S12: =IF(AND(R12>0,Q12>0,R12>Q12),R12-Q12,"") | T12: =IF(AND(R12<0,Q12<0,R12<Q12),R12-Q12,"") | V12: 69550 | W12: 71630 | X12: 71630 | Y12: 15662 | Z12: 4.57 | AA12: 10.0282 | AB12: 0 | AC12: 0
A13: =IFERROR(MATCH(C13,'دیده بان بازار'!$A$5:$A$3994,0 )+4,"Closed") -> 197 | B13: سيمان ‌اروميه‌ | C13: ساروم | D13: C | F13: =IFERROR(_xlfn.LET(_xlpm.lookup_result,_xlfn.XLOOKUP($C13,'دیده بان بازار'!$A$5:$A$3994,'دیده بان بازار'!F$5:F$3994),IF(ISERROR(_xlpm.lookup_result),V13,_xlpm.lookup_result)),V13) -> 199400 | G13: =IFERROR(_xlfn.LET(_xlpm.lookup_result,_xlfn.XLOOKUP($C13,'دیده بان بازار'!$A$5:$A$3994,'دیده بان بازار'!H$5:H$3994),IF(ISERROR(_xlpm.lookup_result),W13,_xlpm.lookup_result)),W13) -> 205300 | H13: =IFERROR(_xlfn.LET(_xlpm.lookup_result,_xlfn.XLOOKUP($C13,'دیده بان بازار'!$A$5:$A$3994,'دیده بان بازار'!K$5:K$3994),IF(ISERROR(_xlpm.lookup_result),X13,_xlpm.lookup_result)),X13) -> 205300 | I13: =IFERROR(_xlfn.LET(_xlpm.lookup_result,_xlfn.XLOOKUP($C13,'دیده بان بازار'!$A$5:$A$3994,'دیده بان بازار'!P$5:P$3994),IF(ISERROR(_xlpm.lookup_result),Y13,_xlpm.lookup_result)),Y13) -> 34336 | J13: =IFERROR(_xlfn.LET(_xlpm.lookup_result,_xlfn.XLOOKUP($C13,'دیده بان بازار'!$A$5:$A$3994,'دیده بان بازار'!Q$5:Q$3994),IF(ISERROR(_xlpm.lookup_result),Z13,_xlpm.lookup_result)),Z13) -> 5.98 | K13: =_xlfn.XLOOKUP(C13,Cement!$Q$7:$Q$35,Cement!$S$7:$S$35,"")/1000 -> 20.53 | L13: =_xlfn.XLOOKUP(C13,'Cement Portfolio'!$O$8:$O$36,'Cement Portfolio'!$AP$8:$AP$36,"") -> 90000 | M13: =_xlfn.XLOOKUP(C13,'Cement Portfolio'!$O$8:$O$36,'Cement Portfolio'!$AQ$8:$AQ$36,"") -> 1831440.2 | O13: =IF(AND(Q13<0,R13<0,Q13<R13),Q13-R13,"") | P13: =IF(AND(Q13>=0,R13>=0,Q13>R13),Q13-R13,"") | Q13: =IFERROR(((K13-AA13)*100)/ABS($K$106),"") -> 0.33037364 | R13: =IFERROR((($AB13*$G13*0.9912*0.0001)-AC13)*100/ABS($AC$108),"") -> 4.9619447 | S13: =IF(AND(R13>0,Q13>0,R13>Q13),R13-Q13,"") -> 4.631571 | T13: =IF(AND(R13<0,Q13<0,R13<Q13),R13-Q13,"") | V13: 193600 | W13: 199400 | X13: 199400 | Y13: 34336 | Z13: 5.81 | AA13: 19.94 | AB13: 90000 | AC13: 1778807.5
A14: =IFERROR(MATCH(C14,'دیده بان بازار'!$A$5:$A$3994,0 )+4,"Closed") -> 2060 | B14: سيمان‌ خزر | C14: سخزر | D14: C | F14: =IFERROR(_xlfn.LET(_xlpm.lookup_result,_xlfn.XLOOKUP($C14,'دیده بان بازار'!$A$5:$A$3994,'دیده بان بازار'!F$5:F$3994),IF(ISERROR(_xlpm.lookup_result),V14,_xlpm.lookup_result)),V14) -> 5370 | G14: =IFERROR(_xlfn.LET(_xlpm.lookup_result,_xlfn.XLOOKUP($C14,'دیده بان بازار'!$A$5:$A$3994,'دیده بان بازار'!H$5:H$3994),IF(ISERROR(_xlpm.lookup_result),W14,_xlpm.lookup_result)),W14) -> 5530 | H14: =IFERROR(_xlfn.LET(_xlpm.lookup_result,_xlfn.XLOOKUP($C14,'دیده بان بازار'!$A$5:$A$3994,'دیده بان بازار'!K$5:K$3994),IF(ISERROR(_xlpm.lookup_result),X14,_xlpm.lookup_result)),X14) -> 5530 | I14: =IFERROR(_xlfn.LET(_xlpm.lookup_result,_xlfn.XLOOKUP($C14,'دیده بان بازار'!$A$5:$A$3994,'دیده بان بازار'!P$5:P$3994),IF(ISERROR(_xlpm.lookup_result),Y14,_xlpm.lookup_result)),Y14) -> 822 | J14: =IFERROR(_xlfn.LET(_xlpm.lookup_result,_xlfn.XLOOKUP($C14,'دیده بان بازار'!$A$5:$A$3994,'دیده بان بازار'!Q$5:Q$3994),IF(ISERROR(_xlpm.lookup_result),Z14,_xlpm.lookup_result)),Z14) -> 6.73 | K14: =_xlfn.XLOOKUP(C14,Cement!$Q$7:$Q$35,Cement!$S$7:$S$35,"")/1000 -> 5.1429 | L14: =_xlfn.XLOOKUP(C14,'Cement Portfolio'!$O$8:$O$36,'Cement Portfolio'!$AP$8:$AP$36,"") -> 100000 | M14: =_xlfn.XLOOKUP(C14,'Cement Portfolio'!$O$8:$O$36,'Cement Portfolio'!$AQ$8:$AQ$36,"") -> 54813.36 | O14: =IF(AND(Q14<0,R14<0,Q14<R14),Q14-R14,"") | P14: =IF(AND(Q14>=0,R14>=0,Q14>R14),Q14-R14,"") | Q14: =IFERROR(((K14-AA14)*100)/ABS($K$106),"") -> 0.083321352 | R14: =IFERROR((($AB14*$G14*0.9912*0.0001)-AC14)*100/ABS($AC$108),"") -> 0.14951246 | S14: =IF(AND(R14>0,Q14>0,R14>Q14),R14-Q14,"") -> 0.066191104 | T14: =IF(AND(R14<0,Q14<0,R14<Q14),R14-Q14,"") | V14: 5220 | W14: 5370 | X14: 5370 | Y14: 822 | Z14: 6.53 | AA14: 4.9941 | AB14: 100000 | AC14: 53227.44
A15: =IFERROR(MATCH(C15,'دیده بان بازار'!$A$5:$A$3994,0 )+4,"Closed") -> 2027 | B15: سيمان باقران | C15: سباقر | D15: C | F15: =IFERROR(_xlfn.LET(_xlpm.lookup_result,_xlfn.XLOOKUP($C15,'دیده بان بازار'!$A$5:$A$3994,'دیده بان بازار'!F$5:F$3994),IF(ISERROR(_xlpm.lookup_result),V15,_xlpm.lookup_result)),V15) -> 235800 | G15: =IFERROR(_xlfn.LET(_xlpm.lookup_result,_xlfn.XLOOKUP($C15,'دیده بان بازار'!$A$5:$A$3994,'دیده بان بازار'!H$5:H$3994),IF(ISERROR(_xlpm.lookup_result),W15,_xlpm.lookup_result)),W15) -> 242800 | H15: =IFERROR(_xlfn.LET(_xlpm.lookup_result,_xlfn.XLOOKUP($C15,'دیده بان بازار'!$A$5:$A$3994,'دیده بان بازار'!K$5:K$3994),IF(ISERROR(_xlpm.lookup_result),X15,_xlpm.lookup_result)),X15) -> 242800 | I15: =IFERROR(_xlfn.LET(_xlpm.lookup_result,_xlfn.XLOOKUP($C15,'دیده بان بازار'!$A$5:$A$3994,'دیده بان بازار'!P$5:P$3994),IF(ISERROR(_xlpm.lookup_result),Y15,_xlpm.lookup_result)),Y15) -> 44486 | J15: =IFERROR(_xlfn.LET(_xlpm.lookup_result,_xlfn.XLOOKUP($C15,'دیده بان بازار'!$A$5:$A$3994,'دیده بان بازار'!Q$5:Q$3994),IF(ISERROR(_xlpm.lookup_result),Z15,_xlpm.lookup_result)),Z15) -> 5.46 | K15: =_xlfn.XLOOKUP(C15,Cement!$Q$7:$Q$35,Cement!$S$7:$S$35,"")/1000 -> 14.568 | L15: =_xlfn.XLOOKUP(C15,'Cement Portfolio'!$O$8:$O$36,'Cement Portfolio'!$AP$8:$AP$36,"") -> 230000 | M15: =_xlfn.XLOOKUP(C15,'Cement Portfolio'!$O$8:$O$36,'Cement Portfolio'!$AQ$8:$AQ$36,"") -> 5535257.3 | O15: =IF(AND(Q15<0,R15<0,Q15<R15),Q15-R15,"") | P15: =IF(AND(Q15>=0,R15>=0,Q15>R15),Q15-R15,"") | Q15: =IFERROR(((K15-AA15)*100)/ABS($K$106),"") -> 0.23518124 | R15: =IFERROR((($AB15*$G15*0.9912*0.0001)-AC15)*100/ABS($AC$108),"") -> 15.044691 | S15: =IF(AND(R15>0,Q15>0,R15>Q15),R15-Q15,"") -> 14.80951 | T15: =IF(AND(R15<0,Q15<0,R15<Q15),R15-Q15,"") | V15: 229000 | W15: 235800 | X15: 235800 | Y15: 44486 | Z15: 5.3 | AA15: 14.148 | AB15: 230000 | AC15: 5375674.1
A16: =IFERROR(MATCH(C16,'دیده بان بازار'!$A$5:$A$3994,0 )+4,"Closed") -> 2229 | B16: سیمان اردستان | C16: اردستان | D16: C | F16: =IFERROR(_xlfn.LET(_xlpm.lookup_result,_xlfn.XLOOKUP($C16,'دیده بان بازار'!$A$5:$A$3994,'دیده بان بازار'!F$5:F$3994),IF(ISERROR(_xlpm.lookup_result),V16,_xlpm.lookup_result)),V16) -> 25710 | G16: =IFERROR(_xlfn.LET(_xlpm.lookup_result,_xlfn.XLOOKUP($C16,'دیده بان بازار'!$A$5:$A$3994,'دیده بان بازار'!H$5:H$3994),IF(ISERROR(_xlpm.lookup_result),W16,_xlpm.lookup_result)),W16) -> 26480 | H16: =IFERROR(_xlfn.LET(_xlpm.lookup_result,_xlfn.XLOOKUP($C16,'دیده بان بازار'!$A$5:$A$3994,'دیده بان بازار'!K$5:K$3994),IF(ISERROR(_xlpm.lookup_result),X16,_xlpm.lookup_result)),X16) -> 26480 | I16: =IFERROR(_xlfn.LET(_xlpm.lookup_result,_xlfn.XLOOKUP($C16,'دیده بان بازار'!$A$5:$A$3994,'دیده بان بازار'!P$5:P$3994),IF(ISERROR(_xlpm.lookup_result),Y16,_xlpm.lookup_result)),Y16) -> 5074 | J16: =IFERROR(_xlfn.LET(_xlpm.lookup_result,_xlfn.XLOOKUP($C16,'دیده بان بازار'!$A$5:$A$3994,'دیده بان بازار'!Q$5:Q$3994),IF(ISERROR(_xlpm.lookup_result),Z16,_xlpm.lookup_result)),Z16) -> 5.22 | K16: =_xlfn.XLOOKUP(C16,Cement!$Q$7:$Q$35,Cement!$S$7:$S$35,"")/1000 -> 6.01096 | L16: =_xlfn.XLOOKUP(C16,'Cement Portfolio'!$O$8:$O$36,'Cement Portfolio'!$AP$8:$AP$36,"") -> 0 | M16: =_xlfn.XLOOKUP(C16,'Cement Portfolio'!$O$8:$O$36,'Cement Portfolio'!$AQ$8:$AQ$36,"") -> 0 | O16: =IF(AND(Q16<0,R16<0,Q16<R16),Q16-R16,"") | P16: =IF(AND(Q16>=0,R16>=0,Q16>R16),Q16-R16,"") -> 0.097874591 | Q16: =IFERROR(((K16-AA16)*100)/ABS($K$106),"") -> 0.097874591 | R16: =IFERROR((($AB16*$G16*0.9912*0.0001)-AC16)*100/ABS($AC$108),"") -> 0 | S16: =IF(AND(R16>0,Q16>0,R16>Q16),R16-Q16,"") | T16: =IF(AND(R16<0,Q16<0,R16<Q16),R16-Q16,"") | V16: 24970 | W16: 25710 | X16: 25710 | Y16: 5074 | Z16: 5.07 | AA16: 5.83617 | AB16: 0 | AC16: 0
A17: =IFERROR(MATCH(C17,'دیده بان بازار'!$A$5:$A$3994,0 )+4,"Closed") -> 1389 | B17: سيمان‌ شمال‌ | C17: سشمال | D17: C | F17: =IFERROR(_xlfn.LET(_xlpm.lookup_result,_xlfn.XLOOKUP($C17,'دیده بان بازار'!$A$5:$A$3994,'دیده بان بازار'!F$5:F$3994),IF(ISERROR(_xlpm.lookup_result),V17,_xlpm.lookup_result)),V17) -> 14190 | G17: =IFERROR(_xlfn.LET(_xlpm.lookup_result,_xlfn.XLOOKUP($C17,'دیده بان بازار'!$A$5:$A$3994,'دیده بان بازار'!H$5:H$3994),IF(ISERROR(_xlpm.lookup_result),W17,_xlpm.lookup_result)),W17) -> 14610 | H17: =IFERROR(_xlfn.LET(_xlpm.lookup_result,_xlfn.XLOOKUP($C17,'دیده بان بازار'!$A$5:$A$3994,'دیده بان بازار'!K$5:K$3994),IF(ISERROR(_xlpm.lookup_result),X17,_xlpm.lookup_result)),X17) -> 14610 | I17: =IFERROR(_xlfn.LET(_xlpm.lookup_result,_xlfn.XLOOKUP($C17,'دیده بان بازار'!$A$5:$A$3994,'دیده بان بازار'!P$5:P$3994),IF(ISERROR(_xlpm.lookup_result),Y17,_xlpm.lookup_result)),Y17) -> 2372 | J17: =IFERROR(_xlfn.LET(_xlpm.lookup_result,_xlfn.XLOOKUP($C17,'دیده بان بازار'!$A$5:$A$3994,'دیده بان بازار'!Q$5:Q$3994),IF(ISERROR(_xlpm.lookup_result),Z17,_xlpm.lookup_result)),Z17) -> 6.16 | K17: =_xlfn.XLOOKUP(C17,Cement!$Q$7:$Q$35,Cement!$S$7:$S$35,"")/1000 -> 7.305 | L17: =_xlfn.XLOOKUP(C17,'Cement Portfolio'!$O$8:$O$36,'Cement Portfolio'!$AP$8:$AP$36,"") -> 72765 | M17: =_xlfn.XLOOKUP(C17,'Cement Portfolio'!$O$8:$O$36,'Cement Portfolio'!$AQ$8:$AQ$36,"") -> 105374.14 | O17: =IF(AND(Q17<0,R17<0,Q17<R17),Q17-R17,"") | P17: =IF(AND(Q17>=0,R17>=0,Q17>R17),Q17-R17,"") | Q17: =IFERROR(((K17-AA17)*100)/ABS($K$106),"") -> 0.11759062 | R17: =IFERROR((($AB17*$G17*0.9912*0.0001)-AC17)*100/ABS($AC$108),"") -> 0.28558094 | S17: =IF(AND(R17>0,Q17>0,R17>Q17),R17-Q17,"") -> 0.16799032 | T17: =IF(AND(R17<0,Q17<0,R17<Q17),R17-Q17,"") | V17: 13780 | W17: 14190 | X17: 14190 | Y17: 2372 | Z17: 5.98 | AA17: 7.095 | AB17: 72765 | AC17: 102344.9
... A34: =IFERROR(MATCH(C34,'دیده بان بازار'!$A$5:$A$3994,0 )+4,"Closed") -> 2722 | B34: سيمان آرتا اردبيل | C34: ساربيل | D34: C | F34: =IFERROR(_xlfn.LET(_xlpm.lookup_result,_xlfn.XLOOKUP($C34,'دیده بان بازار'!$A$5:$A$3994,'دیده بان بازار'!F$5:F$3994),IF(ISERROR(_xlpm.lookup_result),V34,_xlpm.lookup_result)),V34) -> 81220 | G34: =IFERROR(_xlfn.LET(_xlpm.lookup_result,_xlfn.XLOOKUP($C34,'دیده بان بازار'!$A$5:$A$3994,'دیده بان بازار'!H$5:H$3994),IF(ISERROR(_xlpm.lookup_result),W34,_xlpm.lookup_result)),W34) -> 83650 | H34: =IFERROR(_xlfn.LET(_xlpm.lookup_result,_xlfn.XLOOKUP($C34,'دیده بان بازار'!$A$5:$A$3994,'دیده بان بازار'!K$5:K$3994),IF(ISERROR(_xlpm.lookup_result),X34,_xlpm.lookup_result)),X34) -> 83270 | I34: =IFERROR(_xlfn.LET(_xlpm.lookup_result,_xlfn.XLOOKUP($C34,'دیده بان بازار'!$A$5:$A$3994,'دیده بان بازار'!P$5:P$3994),IF(ISERROR(_xlpm.lookup_result),Y34,_xlpm.lookup_result)),Y34) -> 11188 | J34: =IFERROR(_xlfn.LET(_xlpm.lookup_result,_xlfn.XLOOKUP($C34,'دیده بان بازار'!$A$5:$A$3994,'دیده بان بازار'!Q$5:Q$3994),IF(ISERROR(_xlpm.lookup_result),Z34,_xlpm.lookup_result)),Z34) -> 7.44 | K34: =_xlfn.XLOOKUP(C34,Cement!$Q$7:$Q$35,Cement!$S$7:$S$35,"")/1000 -> 12.0456 | L34: =_xlfn.XLOOKUP(C34,'Cement Portfolio'!$O$8:$O$36,'Cement Portfolio'!$AP$8:$AP$36,"") -> 0 | M34: =_xlfn.XLOOKUP(C34,'Cement Portfolio'!$O$8:$O$36,'Cement Portfolio'!$AQ$8:$AQ$36,"") -> 0 | O34: =IF(AND(Q34<0,R34<0,Q34<R34),Q34-R34,"") | P34: =IF(AND(Q34>=0,R34>=0,Q34>R34),Q34-R34,"") -> 0.1830382 | Q34: =IFERROR(((K34-AA34)*100)/ABS($K$106),"") -> 0.1830382 | R34: =IFERROR((($AB34*$G34*0.9912*0.0001)-AC34)*100/ABS($AC$108),"") -> 0 | S34: =IF(AND(R34>0,Q34>0,R34>Q34),R34-Q34,"") | T34: =IF(AND(R34<0,Q34<0,R34<Q34),R34-Q34,"") | V34: 79440 | W34: 81380 | X34: 81220 | Y34: 11188 | Z34: 7.26 | AA34: 11.71872 | AB34: 0 | AC34: 0
A36: =IFERROR(MATCH(C36,'دیده بان بازار'!$A$5:$A$3994,0 )+4,"Closed") -> 2187 | B36: توليدي برنا باطري | C36: خبرنا | D36: =_xlfn.XLOOKUP(C36,MOPFRA!$R$7:$R$56,MOPFRA!$P$7:$P$56,"") -> AP | F36: =IFERROR(_xlfn.LET(_xlpm.lookup_result,_xlfn.XLOOKUP($C36,'دیده بان بازار'!$A$5:$A$3994,'دیده بان بازار'!F$5:F$3994),IF(ISERROR(_xlpm.lookup_result),V36,_xlpm.lookup_result)),V36) -> 6400 | G36: =IFERROR(_xlfn.LET(_xlpm.lookup_result,_xlfn.XLOOKUP($C36,'دیده بان بازار'!$A$5:$A$3994,'دیده بان بازار'!H$5:H$3994),IF(ISERROR(_xlpm.lookup_result),W36,_xlpm.lookup_result)),W36) -> 6590 | H36: =IFERROR(_xlfn.LET(_xlpm.lookup_result,_xlfn.XLOOKUP($C36,'دیده بان بازار'!$A$5:$A$3994,'دیده بان بازار'!K$5:K$3994),IF(ISERROR(_xlpm.lookup_result),X36,_xlpm.lookup_result)),X36) -> 6570 | I36: =IFERROR(_xlfn.LET(_xlpm.lookup_result,_xlfn.XLOOKUP($C36,'دیده بان بازار'!$A$5:$A$3994,'دیده بان بازار'!P$5:P$3994),IF(ISERROR(_xlpm.lookup_result),Y36,_xlpm.lookup_result)),Y36) -> 1058 | J36: =IFERROR(_xlfn.LET(_xlpm.lookup_result,_xlfn.XLOOKUP($C36,'دیده بان بازار'!$A$5:$A$3994,'دیده بان بازار'!Q$5:Q$3994),IF(ISERROR(_xlpm.lookup_result),Z36,_xlpm.lookup_result)),Z36) -> 6.21 | K36: =_xlfn.XLOOKUP(C36,MOPFRA!$R$7:$R$56,MOPFRA!$T$7:$T$56,"")/1000 -> 3.295 | L36: =_xlfn.XLOOKUP(C36,'MOPFRA Portfolio'!$P$8:$P$78,'MOPFRA Portfolio'!$AT$8:$AT$78,"") -> 535000 | M36: =_xlfn.XLOOKUP(C36,'MOPFRA Portfolio'!$P$8:$P$78,'MOPFRA Portfolio'!$AU$8:$AU$78,"") -> 349462.43 | O36: =IF(AND(Q36<0,R36<0,Q36<R36),Q36-R36,"") | P36: =IF(AND(Q36>=0,R36>=0,Q36>R36),Q36-R36,"") | Q36: =IFERROR(((K36-AA36)*100)/ABS($K$106),"") -> 0.058795309 | R36: =IFERROR((($AB36*$G36*0.9912*0.0001)-AC36)*100/ABS($AC$108),"") -> 1.0498578 | S36: =IF(AND(R36>0,Q36>0,R36>Q36),R36-Q36,"") -> 0.99106247 | T36: =IF(AND(R36<0,Q36<0,R36<Q36),R36-Q36,"") | V36: 6250 | W36: 6380 | X36: 6400 | Y36: 1058 | Z36: 6.05 | AA36: 3.19 | AB36: 535000 | AC36: 338326.3
A37: =IFERROR(MATCH(C37,'دیده بان بازار'!$A$5:$A$3994,0 )+4,"Closed") -> 1107 | B37: آلوميناي ايران | C37: آلومينا | D37: =_xlfn.XLOOKUP(C37,MOPFRA!$R$7:$R$56,MOPFRA!$P$7:$P$56,"") -> AL | F37: =IFERROR(_xlfn.LET(_xlpm.lookup_result,_xlfn.XLOOKUP($C37,'دیده بان بازار'!$A$5:$A$3994,'دیده بان بازار'!F$5:F$3994),IF(ISERROR(_xlpm.lookup_result),V37,_xlpm.lookup_result)),V37) -> 148500 | G37: =IFERROR(_xlfn.LET(_xlpm.lookup_result,_xlfn.XLOOKUP($C37,'دیده بان بازار'!$A$5:$A$3994,'دیده بان بازار'!H$5:H$3994),IF(ISERROR(_xlpm.lookup_result),W37,_xlpm.lookup_result)),W37) -> 152900 | H37: =IFERROR(_xlfn.LET(_xlpm.lookup_result,_xlfn.XLOOKUP($C37,'دیده بان بازار'!$A$5:$A$3994,'دیده بان بازار'!K$5:K$3994),IF(ISERROR(_xlpm.lookup_result),X37,_xlpm.lookup_result)),X37) -> 152900 | I37: =IFERROR(_xlfn.LET(_xlpm.lookup_result,_xlfn.XLOOKUP($C37,'دیده بان بازار'!$A$5:$A$3994,'دیده بان بازار'!P$5:P$3994),IF(ISERROR(_xlpm.lookup_result),Y37,_xlpm.lookup_result)),Y37) -> 16822 | J37: =IFERROR(_xlfn.LET(_xlpm.lookup_result,_xlfn.XLOOKUP($C37,'دیده بان بازار'!$A$5:$A$3994,'دیده بان بازار'!Q$5:Q$3994),IF(ISERROR(_xlpm.lookup_result),Z37,_xlpm.lookup_result)),Z37) -> 9.09 | K37: =_xlfn.XLOOKUP(C37,MOPFRA!$R$7:$R$56,MOPFRA!$T$7:$T$56,"")/1000 -> 30.576468 | L37: =_xlfn.XLOOKUP(C37,'MOPFRA Portfolio'!$P$8:$P$78,'MOPFRA Portfolio'!$AT$8:$AT$78,"") -> 0 | M37: =_xlfn.XLOOKUP(C37,'MOPFRA Portfolio'!$P$8:$P$78,'MOPFRA Portfolio'!$AU$8:$AU$78,"") -> 0 | P37: =IF(AND(Q37>=0,R37>=0,Q37>R37),Q37-R37,"") -> 0.49270377 | Q37: =IFERROR(((K37-AA37)*100)/ABS($K$106),"") -> 0.49270377 | R37: =IFERROR((($AB37*$G37*0.9912*0.0001)-AC37)*100/ABS($AC$108),"") -> 0 | V37: 144200 | W37: 148500 | X37: 148500 | Y37: 16822 | Z37: 8.83 | AA37: 29.69657 | AB37: 0 | AC37: 0
A38: =IFERROR(MATCH(C38,'دیده بان بازار'!$A$5:$A$3994,0 )+4,"Closed") -> 2932 | B38: پاكسان‌ | C38: شپاكسا | D38: =_xlfn.XLOOKUP(C38,MOPFRA!$R$7:$R$56,MOPFRA!$P$7:$P$56,"") -> DH | F38: =IFERROR(_xlfn.LET(_xlpm.lookup_result,_xlfn.XLOOKUP($C38,'دیده بان بازار'!$A$5:$A$3994,'دیده بان بازار'!F$5:F$3994),IF(ISERROR(_xlpm.lookup_result),V38,_xlpm.lookup_result)),V38) -> 3340 | G38: =IFERROR(_xlfn.LET(_xlpm.lookup_result,_xlfn.XLOOKUP($C38,'دیده بان بازار'!$A$5:$A$3994,'دیده بان بازار'!H$5:H$3994),IF(ISERROR(_xlpm.lookup_result),W38,_xlpm.lookup_result)),W38) -> 3440 | H38: =IFERROR(_xlfn.LET(_xlpm.lookup_result,_xlfn.XLOOKUP($C38,'دیده بان بازار'!$A$5:$A$3994,'دیده بان بازار'!K$5:K$3994),IF(ISERROR(_xlpm.lookup_result),X38,_xlpm.lookup_result)),X38) -> 3440 | I38: =IFERROR(_xlfn.LET(_xlpm.lookup_result,_xlfn.XLOOKUP($C38,'دیده بان بازار'!$A$5:$A$3994,'دیده بان بازار'!P$5:P$3994),IF(ISERROR(_xlpm.lookup_result),Y38,_xlpm.lookup_result)),Y38) -> 590 | J38: =IFERROR(_xlfn.LET(_xlpm.lookup_result,_xlfn.XLOOKUP($C38,'دیده بان بازار'!$A$5:$A$3994,'دیده بان بازار'!Q$5:Q$3994),IF(ISERROR(_xlpm.lookup_result),Z38,_xlpm.lookup_result)),Z38) -> 5.83 | K38: =_xlfn.XLOOKUP(C38,MOPFRA!$R$7:$R$56,MOPFRA!$T$7:$T$56,"")/1000 -> 6.1232 | L38: =_xlfn.XLOOKUP(C38,'MOPFRA Portfolio'!$P$8:$P$78,'MOPFRA Portfolio'!$AT$8:$AT$78,"") -> 2100000 | M38: =_xlfn.XLOOKUP(C38,'MOPFRA Portfolio'!$P$8:$P$78,'MOPFRA Portfolio'!$AU$8:$AU$78,"") -> 716042.88 | O38: =IF(AND(Q38<0,R38<0,Q38<R38),Q38-R38,"") | P38: =IF(AND(Q38>=0,R38>=0,Q38>R38),Q38-R38,"") | Q38: =IFERROR(((K38-AA38)*100)/ABS($K$106),"") -> 0.099672048 | R38: =IFERROR((($AB38*$G38*0.9912*0.0001)-AC38)*100/ABS($AC$108),"") -> 2.0557963 | S38: =IF(AND(R38>0,Q38>0,R38>Q38),R38-Q38,"") -> 1.9561242 | T38: =IF(AND(R38<0,Q38<0,R38<Q38),R38-Q38,"") | V38: 3250 | W38: 3340 | X38: 3340 | Y38: 590 | Z38: 5.66 | AA38: 5.9452 | AB38: 2200000 | AC38: 728333.76
A39: =IFERROR(MATCH(C39,'دیده بان بازار'!$A$5:$A$3994,0 )+4,"Closed") -> Closed | B39: صنايع بهداشتي ساينا | C39: ساينا | D39: =_xlfn.XLOOKUP(C39,MOPFRA!$R$7:$R$56,MOPFRA!$P$7:$P$56,"") -> DH | F39: =IFERROR(_xlfn.LET(_xlpm.lookup_result,_xlfn.XLOOKUP($C39,'دیده بان بازار'!$A$5:$A$3994,'دیده بان بازار'!F$5:F$3994),IF(ISERROR(_xlpm.lookup_result),V39,_xlpm.lookup_result)),V39) -> 9820 | G39: =IFERROR(_xlfn.LET(_xlpm.lookup_result,_xlfn.XLOOKUP($C39,'دیده بان بازار'!$A$5:$A$3994,'دیده بان بازار'!H$5:H$3994),IF(ISERROR(_xlpm.lookup_result),W39,_xlpm.lookup_result)),W39) -> 10110 | H39: =IFERROR(_xlfn.LET(_xlpm.lookup_result,_xlfn.XLOOKUP($C39,'دیده بان بازار'!$A$5:$A$3994,'دیده بان بازار'!K$5:K$3994),IF(ISERROR(_xlpm.lookup_result),X39,_xlpm.lookup_result)),X39) -> 10110 | I39: =IFERROR(_xlfn.LET(_xlpm.lookup_result,_xlfn.XLOOKUP($C39,'دیده بان بازار'!$A$5:$A$3994,'دیده بان بازار'!P$5:P$3994),IF(ISERROR(_xlpm.lookup_result),Y39,_xlpm.lookup_result)),Y39) -> 1886 | J39: =IFERROR(_xlfn.LET(_xlpm.lookup_result,_xlfn.XLOOKUP($C39,'دیده بان بازار'!$A$5:$A$3994,'دیده بان بازار'!Q$5:Q$3994),IF(ISERROR(_xlpm.lookup_result),Z39,_xlpm.lookup_result)),Z39) -> 5.36 | K39: =_xlfn.XLOOKUP(C39,MOPFRA!$R$7:$R$56,MOPFRA!$T$7:$T$56,"")/1000 -> 2.1231 | L39: =_xlfn.XLOOKUP(C39,'MOPFRA Portfolio'!$P$8:$P$78,'MOPFRA Portfolio'!$AT$8:$AT$78,"") -> 0 | M39: =_xlfn.XLOOKUP(C39,'MOPFRA Portfolio'!$P$8:$P$78,'MOPFRA Portfolio'!$AU$8:$AU$78,"") -> 0 | O39: =IF(AND(Q39<0,R39<0,Q39<R39),Q39-R39,"") | P39: =IF(AND(Q39>=0,R39>=0,Q39>R39),Q39-R39,"") | Q39: =IFERROR(((K39-AA39)*100)/ABS($K$106),"") -> 0 | R39: =IFERROR((($AB39*$G39*0.9912*0.0001)-AC39)*100/ABS($AC$108),"") -> 0 | S39: =IF(AND(R39>0,Q39>0,R39>Q39),R39-Q39,"") | T39: =IF(AND(R39<0,Q39<0,R39<Q39),R39-Q39,"") | V39: 9820 | W39: 10110 | X39: 10110 | Y39: 1886 | Z39: 5.36 | AA39: 2.1231 | AB39: 0 | AC39: 0
A40: =IFERROR(MATCH(C40,'دیده بان بازار'!$A$5:$A$3994,0 )+4,"Closed") -> 1697 | B40: گلتاش‌ | C40: شگل | D40: =_xlfn.XLOOKUP(C40,MOPFRA!$R$7:$R$56,MOPFRA!$P$7:$P$56,"") -> DH | F40: =IFERROR(_xlfn.LET(_xlpm.lookup_result,_xlfn.XLOOKUP($C40,'دیده بان بازار'!$A$5:$A$3994,'دیده بان بازار'!F$5:F$3994),IF(ISERROR(_xlpm.lookup_result),V40,_xlpm.lookup_result)),V40) -> 2839 | G40: =IFERROR(_xlfn.LET(_xlpm.lookup_result,_xlfn.XLOOKUP($C40,'دیده بان بازار'!$A$5:$A$3994,'دیده بان بازار'!H$5:H$3994),IF(ISERROR(_xlpm.lookup_result),W40,_xlpm.lookup_result)),W40) -> 2826 | H40: =IFERROR(_xlfn.LET(_xlpm.lookup_result,_xlfn.XLOOKUP($C40,'دیده بان بازار'!$A$5:$A$3994,'دیده بان بازار'!K$5:K$3994),IF(ISERROR(_xlpm.lookup_result),X40,_xlpm.lookup_result)),X40) -> 2816 | I40: =IFERROR(_xlfn.LET(_xlpm.lookup_result,_xlfn.XLOOKUP($C40,'دیده بان بازار'!$A$5:$A$3994,'دیده بان بازار'!P$5:P$3994),IF(ISERROR(_xlpm.lookup_result),Y40,_xlpm.lookup_result)),Y40) -> 352 | J40: =IFERROR(_xlfn.LET(_xlpm.lookup_result,_xlfn.XLOOKUP($C40,'دیده بان بازار'!$A$5:$A$3994,'دیده بان بازار'!Q$5:Q$3994),IF(ISERROR(_xlpm.lookup_result),Z40,_xlpm.lookup_result)),Z40) -> 8 | K40: =_xlfn.XLOOKUP(C40,MOPFRA!$R$7:$R$56,MOPFRA!$T$7:$T$56,"")/1000 -> 4.8042 | L40: =_xlfn.XLOOKUP(C40,'MOPFRA Portfolio'!$P$8:$P$78,'MOPFRA Portfolio'!$AT$8:$AT$78,"") -> 35288 | M40: =_xlfn.XLOOKUP(C40,'MOPFRA Portfolio'!$P$8:$P$78,'MOPFRA Portfolio'!$AU$8:$AU$78,"") -> 9884.6318 | P40: =IF(AND(Q40>=0,R40>=0,Q40>R40),Q40-R40,"") -> 0.01392908 | Q40: =IFERROR(((K40-AA40)*100)/ABS($K$106),"") -> 0.03046157 | R40: =IFERROR((($AB40*$G40*0.9912*0.0001)-AC40)*100/ABS($AC$108),"") -> 0.016532489 | V40: 2000 | W40: 2794 | X40: 2839 | Y40: 352 | Z40: 8.07 | AA40: 4.7498 | AB40: 55288 | AC40: 15311.529
A41: =IFERROR(MATCH(C41,'دیده بان بازار'!$A$5:$A$3994,0 )+4,"Closed") -> 1456 | B41: سالمين‌ | C41: غسالم | D41: =_xlfn.XLOOKUP(C41,MOPFRA!$R$7:$R$56,MOPFRA!$P$7:$P$56,"") -> F | F41: =IFERROR(_xlfn.LET(_xlpm.lookup_result,_xlfn.XLOOKUP($C41,'دیده بان بازار'!$A$5:$A$3994,'دیده بان بازار'!F$5:F$3994),IF(ISERROR(_xlpm.lookup_result),V41,_xlpm.lookup_result)),V41) -> 7910 | G41: =IFERROR(_xlfn.LET(_xlpm.lookup_result,_xlfn.XLOOKUP($C41,'دیده بان بازار'!$A$5:$A$3994,'دیده بان بازار'!H$5:H$3994),IF(ISERROR(_xlpm.lookup_result),W41,_xlpm.lookup_result)),W41) -> 8140 | H41: =IFERROR(_xlfn.LET(_xlpm.lookup_result,_xlfn.XLOOKUP($C41,'دیده بان بازار'!$A$5:$A$3994,'دیده بان بازار'!K$5:K$3994),IF(ISERROR(_xlpm.lookup_result),X41,_xlpm.lookup_result)),X41) -> 8140 | I41: =IFERROR(_xlfn.LET(_xlpm.lookup_result,_xlfn.XLOOKUP($C41,'دیده بان بازار'!$A$5:$A$3994,'دیده بان بازار'!P$5:P$3994),IF(ISERROR(_xlpm.lookup_result),Y41,_xlpm.lookup_result)),Y41) -> 1348 | J41: =IFERROR(_xlfn.LET(_xlpm.lookup_result,_xlfn.XLOOKUP($C41,'دیده بان بازار'!$A$5:$A$3994,'دیده بان بازار'!Q$5:Q$3994),IF(ISERROR(_xlpm.lookup_result),Z41,_xlpm.lookup_result)),Z41) -> 6.04 | K41: =_xlfn.XLOOKUP(C41,MOPFRA!$R$7:$R$56,MOPFRA!$T$7:$T$56,"")/1000 -> 4.884 | L41: =_xlfn.XLOOKUP(C41,'MOPFRA Portfolio'!$P$8:$P$78,'MOPFRA Portfolio'!$AT$8:$AT$78,"") -> 160000 | M41: =_xlfn.XLOOKUP(C41,'MOPFRA Portfolio'!$P$8:$P$78,'MOPFRA Portfolio'!$AU$8:$AU$78,"") -> 129093.89 | O41: =IF(AND(Q41<0,R41<0,Q41<R41),Q41-R41,"") | P41: =IF(AND(Q41>=0,R41>=0,Q41>R41),Q41-R41,"") | Q41: =IFERROR(((K41-AA41)*100)/ABS($K$106),"") -> 0.077273835 | R41: =IFERROR((($AB41*$G41*0.9912*0.0001)-AC41)*100/ABS($AC$108),"") -> 0.34387865 | S41: =IF(AND(R41>0,Q41>0,R41>Q41),R41-Q41,"") -> 0.26660482 | T41: =IF(AND(R41<0,Q41<0,R41<Q41),R41-Q41,"") | V41: 7680 | W41: 7910 | X41: 7910 | Y41: 1348 | Z41: 5.87 | AA41: 4.746 | AB41: 160000 | AC41: 125446.27
A42: =IFERROR(MATCH(C42,'دیده بان بازار'!$A$5:$A$3994,0 )+4,"Closed") -> 2099 | B42: شركت صنايع غذايي مينو شرق | C42: غمينو | D42: =_xlfn.XLOOKUP(C42,MOPFRA!$R$7:$R$56,MOPFRA!$P$7:$P$56,"") -> F | F42: =IFERROR(_xlfn.LET(_xlpm.lookup_result,_xlfn.XLOOKUP($C42,'دیده بان بازار'!$A$5:$A$3994,'دیده بان بازار'!F$5:F$3994),IF(ISERROR(_xlpm.lookup_result),V42,_xlpm.lookup_result)),V42) -> 8270 | G42: =IFERROR(_xlfn.LET(_xlpm.lookup_result,_xlfn.XLOOKUP($C42,'دیده بان بازار'!$A$5:$A$3994,'دیده بان بازار'!H$5:H$3994),IF(ISERROR(_xlpm.lookup_result),W42,_xlpm.lookup_result)),W42) -> 8410 | H42: =IFERROR(_xlfn.LET(_xlpm.lookup_result,_xlfn.XLOOKUP($C42,'دیده بان بازار'!$A$5:$A$3994,'دیده بان بازار'!K$5:K$3994),IF(ISERROR(_xlpm.lookup_result),X42,_xlpm.lookup_result)),X42) -> 8370 | I42: =IFERROR(_xlfn.LET(_xlpm.lookup_result,_xlfn.XLOOKUP($C42,'دیده بان بازار'!$A$5:$A$3994,'دیده بان بازار'!P$5:P$3994),IF(ISERROR(_xlpm.lookup_result),Y42,_xlpm.lookup_result)),Y42) -> 1231 | J42: =IFERROR(_xlfn.LET(_xlpm.lookup_result,_xlfn.XLOOKUP($C42,'دیده بان بازار'!$A$5:$A$3994,'دیده بان بازار'!Q$5:Q$3994),IF(ISERROR(_xlpm.lookup_result),Z42,_xlpm.lookup_result)),Z42) -> 6.8 | K42: =_xlfn.XLOOKUP(C42,MOPFRA!$R$7:$R$56,MOPFRA!$T$7:$T$56,"")/1000 -> 5.887 | L42: =_xlfn.XLOOKUP(C42,'MOPFRA Portfolio'!$P$8:$P$78,'MOPFRA Portfolio'!$AT$8:$AT$78,"") -> 650000 | M42: =_xlfn.XLOOKUP(C42,'MOPFRA Portfolio'!$P$8:$P$78,'MOPFRA Portfolio'!$AU$8:$AU$78,"") -> 541839.48 | O42: =IF(AND(Q42<0,R42<0,Q42<R42),Q42-R42,"") | P42: =IF(AND(Q42>=0,R42>=0,Q42>R42),Q42-R42,"") | Q42: =IFERROR(((K42-AA42)*100)/ABS($K$106),"") -> 0.054875622 | R42: =IFERROR((($AB42*$G42*0.9912*0.0001)-AC42)*100/ABS($AC$108),"") -> 0.8503521 | S42: =IF(AND(R42>0,Q42>0,R42>Q42),R42-Q42,"") -> 0.79547647 | T42: =IF(AND(R42<0,Q42<0,R42<Q42),R42-Q42,"") | V42: 8050 | W42: 8270 | X42: 8270 | Y42: 1231 | Z42: 6.72 | AA42: 5.789 | AB42: 650000 | AC42: 532819.56
A43: =IFERROR(MATCH(C43,'دیده بان بازار'!$A$5:$A$3994,0 )+4,"Closed") -> 2106 | B43: توليدي‌مهرام‌ | C43: غمهرا | D43: =_xlfn.XLOOKUP(C43,MOPFRA!$R$7:$R$56,MOPFRA!$P$7:$P$56,"") -> F | F43: =IFERROR(_xlfn.LET(_xlpm.lookup_result,_xlfn.XLOOKUP($C43,'دیده بان بازار'!$A$5:$A$3994,'دیده بان بازار'!F$5:F$3994),IF(ISERROR(_xlpm.lookup_result),V43,_xlpm.lookup_result)),V43) -> 17340 | G43: =IFERROR(_xlfn.LET(_xlpm.lookup_result,_xlfn.XLOOKUP($C43,'دیده بان بازار'!$A$5:$A$3994,'دیده بان بازار'!H$5:H$3994),IF(ISERROR(_xlpm.lookup_result),W43,_xlpm.lookup_result)),W43) -> 17860 | H43: =IFERROR(_xlfn.LET(_xlpm.lookup_result,_xlfn.XLOOKUP($C43,'دیده بان بازار'!$A$5:$A$3994,'دیده بان بازار'!K$5:K$3994),IF(ISERROR(_xlpm.lookup_result),X43,_xlpm.lookup_result)),X43) -> 17850 | I43: =IFERROR(_xlfn.LET(_xlpm.lookup_result,_xlfn.XLOOKUP($C43,'دیده بان بازار'!$A$5:$A$3994,'دیده بان بازار'!P$5:P$3994),IF(ISERROR(_xlpm.lookup_result),Y43,_xlpm.lookup_result)),Y43) -> 2564 | J43: =IFERROR(_xlfn.LET(_xlpm.lookup_result,_xlfn.XLOOKUP($C43,'دیده بان بازار'!$A$5:$A$3994,'دیده بان بازار'!Q$5:Q$3994),IF(ISERROR(_xlpm.lookup_result),Z43,_xlpm.lookup_result)),Z43) -> 6.96 | K43: =_xlfn.XLOOKUP(C43,MOPFRA!$R$7:$R$56,MOPFRA!$T$7:$T$56,"")/1000 -> 8.93 | L43: =_xlfn.XLOOKUP(C43,'MOPFRA Portfolio'!$P$8:$P$78,'MOPFRA Portfolio'!$AT$8:$AT$78,"") -> 110000 | M43: =_xlfn.XLOOKUP(C43,'MOPFRA Portfolio'!$P$8:$P$78,'MOPFRA Portfolio'!$AU$8:$AU$78,"") -> 194731.15 | O43: =IF(AND(Q43<0,R43<0,Q43<R43),Q43-R43,"") | P43: =IF(AND(Q43>=0,R43>=0,Q43>R43),Q43-R43,"") | Q43: =IFERROR(((K43-AA43)*100)/ABS($K$106),"") -> 0.14558838 | R43: =IFERROR((($AB43*$G43*0.9912*0.0001)-AC43)*100/ABS($AC$108),"") -> 0.53450703 | S43: =IF(AND(R43>0,Q43>0,R43>Q43),R43-Q43,"") -> 0.38891865 | T43: =IF(AND(R43<0,Q43<0,R43<Q43),R43-Q43,"") | V43: 16840 | W43: 17340 | X43: 17340 | Y43: 2564 | Z43: 6.76 | AA43: 8.67 | AB43: 110000 | AC43: 189061.49
A44: =IFERROR(MATCH(C44,'دیده بان بازار'!$A$5:$A$3994,0 )+4,"Closed") -> 2376 | B44: صنعت غذايي كورش | C44: غكورش | D44: =_xlfn.XLOOKUP(C44,MOPFRA!$R$7:$R$56,MOPFRA!$P$7:$P$56,"") -> F | F44: =IFERROR(_xlfn.LET(_xlpm.lookup_result,_xlfn.XLOOKUP($C44,'دیده بان بازار'!$A$5:$A$3994,'دیده بان بازار'!F$5:F$3994),IF(ISERROR(_xlpm.lookup_result),V44,_xlpm.lookup_result)),V44) -> 18640 | G44: =IFERROR(_xlfn.LET(_xlpm.lookup_result,_xlfn.XLOOKUP($C44,'دیده بان بازار'!$A$5:$A$3994,'دیده بان بازار'!H$5:H$3994),IF(ISERROR(_xlpm.lookup_result),W44,_xlpm.lookup_result)),W44) -> 19190 | H44: =IFERROR(_xlfn.LET(_xlpm.lookup_result,_xlfn.XLOOKUP($C44,'دیده بان بازار'!$A$5:$A$3994,'دیده بان بازار'!K$5:K$3994),IF(ISERROR(_xlpm.lookup_result),X44,_xlpm.lookup_result)),X44) -> 19170 | I44: =IFERROR(_xlfn.LET(_xlpm.lookup_result,_xlfn.XLOOKUP($C44,'دیده بان بازار'!$A$5:$A$3994,'دیده بان بازار'!P$5:P$3994),IF(ISERROR(_xlpm.lookup_result),Y44,_xlpm.lookup_result)),Y44) -> 2993 | J44: =IFERROR(_xlfn.LET(_xlpm.lookup_result,_xlfn.XLOOKUP($C44,'دیده بان بازار'!$A$5:$A$3994,'دیده بان بازار'!Q$5:Q$3994),IF(ISERROR(_xlpm.lookup_result),Z44,_xlpm.lookup_result)),Z44) -> 6.4 | K44: =_xlfn.XLOOKUP(C44,MOPFRA!$R$7:$R$56,MOPFRA!$T$7:$T$56,"")/1000 -> 84.436 | L44: =_xlfn.XLOOKUP(C44,'MOPFRA Portfolio'!$P$8:$P$78,'MOPFRA Portfolio'!$AT$8:$AT$78,"") -> 0 | M44: =_xlfn.XLOOKUP(C44,'MOPFRA Portfolio'!$P$8:$P$78,'MOPFRA Portfolio'!$AU$8:$AU$78,"") -> 0 | P44: =IF(AND(Q44>=0,R44>=0,Q44>R44),Q44-R44,"") -> 1.453644 | Q44: =IFERROR(((K44-AA44)*100)/ABS($K$106),"") -> 1.453644 | R44: =IFERROR((($AB44*$G44*0.9912*0.0001)-AC44)*100/ABS($AC$108),"") -> 0 | V44: 18110 | W44: 18600 | X44: 18640 | Y44: 2993 | Z44: 6.23 | AA44: 81.84 | AB44: 0 | AC44: 0
A45: =IFERROR(MATCH(C45,'دیده بان بازار'!$A$5:$A$3994,0 )+4,"Closed") -> 254 | B45: صنعتي زر ماكارون | C45: غزر | D45: =_xlfn.XLOOKUP(C45,MOPFRA!$R$7:$R$56,MOPFRA!$P$7:$P$56,"") -> F | F45: =IFERROR(_xlfn.LET(_xlpm.lookup_result,_xlfn.XLOOKUP($C45,'دیده بان بازار'!$A$5:$A$3994,'دیده بان بازار'!F$5:F$3994),IF(ISERROR(_xlpm.lookup_result),V45,_xlpm.lookup_result)),V45) -> 3264 | G45: =IFERROR(_xlfn.LET(_xlpm.lookup_result,_xlfn.XLOOKUP($C45,'دیده بان بازار'!$A$5:$A$3994,'دیده بان بازار'!H$5:H$3994),IF(ISERROR(_xlpm.lookup_result),W45,_xlpm.lookup_result)),W45) -> 3361 | H45: =IFERROR(_xlfn.LET(_xlpm.lookup_result,_xlfn.XLOOKUP($C45,'دیده بان بازار'!$A$5:$A$3994,'دیده بان بازار'!K$5:K$3994),IF(ISERROR(_xlpm.lookup_result),X45,_xlpm.lookup_result)),X45) -> 3361 | I45: =IFERROR(_xlfn.LET(_xlpm.lookup_result,_xlfn.XLOOKUP($C45,'دیده بان بازار'!$A$5:$A$3994,'دیده بان بازار'!P$5:P$3994),IF(ISERROR(_xlpm.lookup_result),Y45,_xlpm.lookup_result)),Y45) -> 620 | J45: =IFERROR(_xlfn.LET(_xlpm.lookup_result,_xlfn.XLOOKUP($C45,'دیده بان بازار'!$A$5:$A$3994,'دیده بان بازار'!Q$5:Q$3994),IF(ISERROR(_xlpm.lookup_result),Z45,_xlpm.lookup_result)),Z45) -> 5.42 | K45: =_xlfn.XLOOKUP(C45,MOPFRA!$R$7:$R$56,MOPFRA!$T$7:$T$56,"")/1000 -> 14.4523 | L45: =_xlfn.XLOOKUP(C45,'MOPFRA Portfolio'!$P$8:$P$78,'MOPFRA Portfolio'!$AT$8:$AT$78,"") -> 0 | M45: =_xlfn.XLOOKUP(C45,'MOPFRA Portfolio'!$P$8:$P$78,'MOPFRA Portfolio'!$AU$8:$AU$78,"") -> 0 | P45: =IF(AND(Q45>=0,R45>=0,Q45>R45),Q45-R45,"") -> 0.23355737 | Q45: =IFERROR(((K45-AA45)*100)/ABS($K$106),"") -> 0.23355737 | R45: =IFERROR((($AB45*$G45*0.9912*0.0001)-AC45)*100/ABS($AC$108),"") -> 0 | V45: 3169 | W45: 3264 | X45: 3264 | Y45: 620 | Z45: 5.26 | AA45: 14.0352 | AB45: 0 | AC45: 0
A46: =IFERROR(MATCH(C46,'دیده بان بازار'!$A$5:$A$3994,0 )+4,"Closed") -> 1749 | B46: كشاورزي و دامپروري فجر اصفهان | C46: زفجر | D46: =_xlfn.XLOOKUP(C46,MOPFRA!$R$7:$R$56,MOPFRA!$P$7:$P$56,"") -> F | F46: =IFERROR(_xlfn.LET(_xlpm.lookup_result,_xlfn.XLOOKUP($C46,'دیده بان بازار'!$A$5:$A$3994,'دیده بان بازار'!F$5:F$3994),IF(ISERROR(_xlpm.lookup_result),V46,_xlpm.lookup_result)),V46) -> 44440 | G46: =IFERROR(_xlfn.LET(_xlpm.lookup_result,_xlfn.XLOOKUP($C46,'دیده بان بازار'!$A$5:$A$3994,'دیده بان بازار'!H$5:H$3994),IF(ISERROR(_xlpm.lookup_result),W46,_xlpm.lookup_result)),W46) -> 45770 | H46: =IFERROR(_xlfn.LET(_xlpm.lookup_result,_xlfn.XLOOKUP($C46,'دیده بان بازار'!$A$5:$A$3994,'دیده بان بازار'!K$5:K$3994),IF(ISERROR(_xlpm.lookup_result),X46,_xlpm.lookup_result)),X46) -> 45770 | I46: =IFERROR(_xlfn.LET(_xlpm.lookup_result,_xlfn.XLOOKUP($C46,'دیده بان بازار'!$A$5:$A$3994,'دیده بان بازار'!P$5:P$3994),IF(ISERROR(_xlpm.lookup_result),Y46,_xlpm.lookup_result)),Y46) -> 7903 | J46: =IFERROR(_xlfn.LET(_xlpm.lookup_result,_xlfn.XLOOKUP($C46,'دیده بان بازار'!$A$5:$A$3994,'دیده بان بازار'!Q$5:Q$3994),IF(ISERROR(_xlpm.lookup_result),Z46,_xlpm.lookup_result)),Z46) -> 5.79 | K46: =_xlfn.XLOOKUP(C46,MOPFRA!$R$7:$R$56,MOPFRA!$T$7:$T$56,"")/1000 -> 4.1193 | L46: =_xlfn.XLOOKUP(C46,'MOPFRA Portfolio'!$P$8:$P$78,'MOPFRA Portfolio'!$AT$8:$AT$78,"") -> 10000 | M46: =_xlfn.XLOOKUP(C46,'MOPFRA Portfolio'!$P$8:$P$78,'MOPFRA Portfolio'!$AU$8:$AU$78,"") -> 45367.224 | P46: =IF(AND(Q46>=0,R46>=0,Q46>R46),Q46-R46,"") | Q46: =IFERROR(((K46-AA46)*100)/ABS($K$106),"") -> 0.063498934 | R46: =IFERROR((($AB46*$G46*0.9912*0.0001)-AC46)*100/ABS($AC$108),"") -> 0.11774106 | V46: 43220 | W46: 44510 | X46: 44440 | Y46: 7903 | Z46: 5.62 | AA46: 4.0059 | AB46: 10000 | AC46: 44118.312
A47: =IFERROR(MATCH(C47,'دیده بان بازار'!$A$5:$A$3994,0 )+4,"Closed") -> 2338 | B47: صنايع الكترونيك ماديران | C47: الكتروماد | D47: =_xlfn.XLOOKUP(C47,MOPFRA!$R$7:$R$56,MOPFRA!$P$7:$P$56,"") -> HH | F47: =IFERROR(_xlfn.LET(_xlpm.lookup_result,_xlfn.XLOOKUP($C47,'دیده بان بازار'!$A$5:$A$3994,'دیده بان بازار'!F$5:F$3994),IF(ISERROR(_xlpm.lookup_result),V47,_xlpm.lookup_result)),V47) -> 3520 | G47: =IFERROR(_xlfn.LET(_xlpm.lookup_result,_xlfn.XLOOKUP($C47,'دیده بان بازار'!$A$5:$A$3994,'دیده بان بازار'!H$5:H$3994),IF(ISERROR(_xlpm.lookup_result),W47,_xlpm.lookup_result)),W47) -> 3620 | H47: =IFERROR(_xlfn.LET(_xlpm.lookup_result,_xlfn.XLOOKUP($C47,'دیده بان بازار'!$A$5:$A$3994,'دیده بان بازار'!K$5:K$3994),IF(ISERROR(_xlpm.lookup_result),X47,_xlpm.lookup_result)),X47) -> 3620 | I47: =IFERROR(_xlfn.LET(_xlpm.lookup_result,_xlfn.XLOOKUP($C47,'دیده بان بازار'!$A$5:$A$3994,'دیده بان بازار'!P$5:P$3994),IF(ISERROR(_xlpm.lookup_result),Y47,_xlpm.lookup_result)),Y47) -> 957 | J47: =IFERROR(_xlfn.LET(_xlpm.lookup_result,_xlfn.XLOOKUP($C47,'دیده بان بازار'!$A$5:$A$3994,'دیده بان بازار'!Q$5:Q$3994),IF(ISERROR(_xlpm.lookup_result),Z47,_xlpm.lookup_result)),Z47) -> 3.78 | K47: =_xlfn.XLOOKUP(C47,MOPFRA!$R$7:$R$56,MOPFRA!$T$7:$T$56,"")/1000 -> 3.258 | L47: =_xlfn.XLOOKUP(C47,'MOPFRA Portfolio'!$P$8:$P$78,'MOPFRA Portfolio'!$AT$8:$AT$78,"") -> 600000 | M47: =_xlfn.XLOOKUP(C47,'MOPFRA Portfolio'!$P$8:$P$78,'MOPFRA Portfolio'!$AU$8:$AU$78,"") -> 215288.64 | O47: =IF(AND(Q47<0,R47<0,Q47<R47),Q47-R47,"") | P47: =IF(AND(Q47>=0,R47>=0,Q47>R47),Q47-R47,"") | Q47: =IFERROR(((K47-AA47)*100)/ABS($K$106),"") -> 0.050395979 | R47: =IFERROR((($AB47*$G47*0.9912*0.0001)-AC47)*100/ABS($AC$108),"") -> 0.28033586 | S47: =IF(AND(R47>0,Q47>0,R47>Q47),R47-Q47,"") -> 0.22993988 | T47: =IF(AND(R47<0,Q47<0,R47<Q47),R47-Q47,"") | V47: 3420 | W47: 3520 | X47: 3520 | Y47: 957 | Z47: 3.68 | AA47: 3.168 | AB47: 300000 | AC47: 104670.72
A48: =IFERROR(MATCH(C48,'دیده بان بازار'!$A$5:$A$3994,0 )+4,"Closed") -> 1191 | B48: پارس‌ خزر | C48: لخزر | D48: =_xlfn.XLOOKUP(C48,MOPFRA!$R$7:$R$56,MOPFRA!$P$7:$P$56,"") -> HL | F48: =IFERROR(_xlfn.LET(_xlpm.lookup_result,_xlfn.XLOOKUP($C48,'دیده بان بازار'!$A$5:$A$3994,'دیده بان بازار'!F$5:F$3994),IF(ISERROR(_xlpm.lookup_result),V48,_xlpm.lookup_result)),V48) -> 3290 | G48: =IFERROR(_xlfn.LET(_xlpm.lookup_result,_xlfn.XLOOKUP($C48,'دیده بان بازار'!$A$5:$A$3994,'دیده بان بازار'!H$5:H$3994),IF(ISERROR(_xlpm.lookup_result),W48,_xlpm.lookup_result)),W48) -> 3380 | H48: =IFERROR(_xlfn.LET(_xlpm.lookup_result,_xlfn.XLOOKUP($C48,'دیده بان بازار'!$A$5:$A$3994,'دیده بان بازار'!K$5:K$3994),IF(ISERROR(_xlpm.lookup_result),X48,_xlpm.lookup_result)),X48) -> 3380 | I48: =IFERROR(_xlfn.LET(_xlpm.lookup_result,_xlfn.XLOOKUP($C48,'دیده بان بازار'!$A$5:$A$3994,'دیده بان بازار'!P$5:P$3994),IF(ISERROR(_xlpm.lookup_result),Y48,_xlpm.lookup_result)),Y48) -> 1120 | J48: =IFERROR(_xlfn.LET(_xlpm.lookup_result,_xlfn.XLOOKUP($C48,'دیده بان بازار'!$A$5:$A$3994,'دیده بان بازار'!Q$5:Q$3994),IF(ISERROR(_xlpm.lookup_result),Z48,_xlpm.lookup_result)),Z48) -> 3.02 | K48: =_xlfn.XLOOKUP(C48,MOPFRA!$R$7:$R$56,MOPFRA!$T$7:$T$56,"")/1000 -> 3.38 | L48: =_xlfn.XLOOKUP(C48,'MOPFRA Portfolio'!$P$8:$P$78,'MOPFRA Portfolio'!$AT$8:$AT$78,"") -> 0 | M48: =_xlfn.XLOOKUP(C48,'MOPFRA Portfolio'!$P$8:$P$78,'MOPFRA Portfolio'!$AU$8:$AU$78,"") -> 0 | O48: =IF(AND(Q48<0,R48<0,Q48<R48),Q48-R48,"") | P48: =IF(AND(Q48>=0,R48>=0,Q48>R48),Q48-R48,"") -> 0.050395979 | Q48: =IFERROR(((K48-AA48)*100)/ABS($K$106),"") -> 0.050395979 | R48: =IFERROR((($AB48*$G48*0.9912*0.0001)-AC48)*100/ABS($AC$108),"") -> 0 | S48: =IF(AND(R48>0,Q48>0,R48>Q48),R48-Q48,"") | T48: =IF(AND(R48<0,Q48<0,R48<Q48),R48-Q48,"") | V48: 3200 | W48: 3290 | X48: 3290 | Y48: 1120 | Z48: 2.94 | AA48: 3.29 | AB48: 0 | AC48: 0
A49: =IFERROR(MATCH(C49,'دیده بان بازار'!$A$5:$A$3994,0 )+4,"Closed") -> 1875 | B49: توسعه فن افزار توسن | C49: فن‌ افزار | D49: =_xlfn.XLOOKUP(C49,MOPFRA!$R$7:$R$56,MOPFRA!$P$7:$P$56,"") -> IT | F49: =IFERROR(_xlfn.LET(_xlpm.lookup_result,_xlfn.XLOOKUP($C49,'دیده بان بازار'!$A$5:$A$3994,'دیده بان بازار'!F$5:F$3994),IF(ISERROR(_xlpm.lookup_result),V49,_xlpm.lookup_result)),V49) -> 7230 | G49: =IFERROR(_xlfn.LET(_xlpm.lookup_result,_xlfn.XLOOKUP($C49,'دیده بان بازار'!$A$5:$A$3994,'دیده بان بازار'!H$5:H$3994),IF(ISERROR(_xlpm.lookup_result),W49,_xlpm.lookup_result)),W49) -> 7440 | H49: =IFERROR(_xlfn.LET(_xlpm.lookup_result,_xlfn.XLOOKUP($C49,'دیده بان بازار'!$A$5:$A$3994,'دیده بان بازار'!K$5:K$3994),IF(ISERROR(_xlpm.lookup_result),X49,_xlpm.lookup_result)),X49) -> 7440 | I49: =IFERROR(_xlfn.LET(_xlpm.lookup_result,_xlfn.XLOOKUP($C49,'دیده بان بازار'!$A$5:$A$3994,'دیده بان بازار'!P$5:P$3994),IF(ISERROR(_xlpm.lookup_result),Y49,_xlpm.lookup_result)),Y49) -> 1478 | J49: =IFERROR(_xlfn.LET(_xlpm.lookup_result,_xlfn.XLOOKUP($C49,'دیده بان بازار'!$A$5:$A$3994,'دیده بان بازار'!Q$5:Q$3994),IF(ISERROR(_xlpm.lookup_result),Z49,_xlpm.lookup_result)),Z49) -> 5.03 | K49: =_xlfn.XLOOKUP(C49,MOPFRA!$R$7:$R$56,MOPFRA!$T$7:$T$56,"")/1000 -> 4.464 | L49: =_xlfn.XLOOKUP(C49,'MOPFRA Portfolio'!$P$8:$P$78,'MOPFRA Portfolio'!$AT$8:$AT$78,"") -> 0 | M49: =_xlfn.XLOOKUP(C49,'MOPFRA Portfolio'!$P$8:$P$78,'MOPFRA Portfolio'!$AU$8:$AU$78,"") -> 0 | O49: =IF(AND(Q49<0,R49<0,Q49<R49),Q49-R49,"") | P49: =IF(AND(Q49>=0,R49>=0,Q49>R49),Q49-R49,"") -> 0.070554371 | Q49: =IFERROR(((K49-AA49)*100)/ABS($K$106),"") -> 0.070554371 | R49: =IFERROR((($AB49*$G49*0.9912*0.0001)-AC49)*100/ABS($AC$108),"") -> 0 | S49: =IF(AND(R49>0,Q49>0,R49>Q49),R49-Q49,"") | T49: =IF(AND(R49<0,Q49<0,R49<Q49),R49-Q49,"") | V49: 7020 | W49: 7230 | X49: 7230 | Y49: 1478 | Z49: 4.89 | AA49: 4.338 | AB49: 0 | AC49: 0
A50: =IFERROR(MATCH(C50,'دیده بان بازار'!$A$5:$A$3994,0 )+4,"Closed") -> 2917 | B50: گروه‌صنعتي‌سپاهان‌ | C50: فسپا | D50: =_xlfn.XLOOKUP(C50,MOPFRA!$R$7:$R$56,MOPFRA!$P$7:$P$56,"") -> M | F50: =IFERROR(_xlfn.LET(_xlpm.lookup_result,_xlfn.XLOOKUP($C50,'دیده بان بازار'!$A$5:$A$3994,'دیده بان بازار'!F$5:F$3994),IF(ISERROR(_xlpm.lookup_result),V50,_xlpm.lookup_result)),V50) -> 4510 | G50: =IFERROR(_xlfn.LET(_xlpm.lookup_result,_xlfn.XLOOKUP($C50,'دیده بان بازار'!$A$5:$A$3994,'دیده بان بازار'!H$5:H$3994),IF(ISERROR(_xlpm.lookup_result),W50,_xlpm.lookup_result)),W50) -> 4640 | H50: =IFERROR(_xlfn.LET(_xlpm.lookup_result,_xlfn.XLOOKUP($C50,'دیده بان بازار'!$A$5:$A$3994,'دیده بان بازار'!K$5:K$3994),IF(ISERROR(_xlpm.lookup_result),X50,_xlpm.lookup_result)),X50) -> 4640 | I50: =IFERROR(_xlfn.LET(_xlpm.lookup_result,_xlfn.XLOOKUP($C50,'دیده بان بازار'!$A$5:$A$3994,'دیده بان بازار'!P$5:P$3994),IF(ISERROR(_xlpm.lookup_result),Y50,_xlpm.lookup_result)),Y50) -> 1216 | J50: =IFERROR(_xlfn.LET(_xlpm.lookup_result,_xlfn.XLOOKUP($C50,'دیده بان بازار'!$A$5:$A$3994,'دیده بان بازار'!Q$5:Q$3994),IF(ISERROR(_xlpm.lookup_result),Z50,_xlpm.lookup_result)),Z50) -> 3.82 | K50: =_xlfn.XLOOKUP(C50,MOPFRA!$R$7:$R$56,MOPFRA!$T$7:$T$56,"")/1000 -> 5.8 | L50: =_xlfn.XLOOKUP(C50,'MOPFRA Portfolio'!$P$8:$P$78,'MOPFRA Portfolio'!$AT$8:$AT$78,"") -> 800000 | M50: =_xlfn.XLOOKUP(C50,'MOPFRA Portfolio'!$P$8:$P$78,'MOPFRA Portfolio'!$AU$8:$AU$78,"") -> 367933.44 | O50: =IF(AND(Q50<0,R50<0,Q50<R50),Q50-R50,"") | P50: =IF(AND(Q50>=0,R50>=0,Q50>R50),Q50-R50,"") | Q50: =IFERROR(((K50-AA50)*100)/ABS($K$106),"") -> 0.09099274 | R50: =IFERROR((($AB50*$G50*0.9912*0.0001)-AC50)*100/ABS($AC$108),"") -> 0.97183097 | S50: =IF(AND(R50>0,Q50>0,R50>Q50),R50-Q50,"") -> 0.88083823 | T50: =IF(AND(R50<0,Q50<0,R50<Q50),R50-Q50,"") | V50: 4380 | W50: 4510 | X50: 4510 | Y50: 1216 | Z50: 3.71 | AA50: 5.6375 | AB50: 800000 | AC50: 357624.96
A51: =IFERROR(MATCH(C51,'دیده بان بازار'!$A$5:$A$3994,0 )+4,"Closed") -> 211 | B51: فولاد اميركبيركاشان | C51: فجر | D51: =_xlfn.XLOOKUP(C51,MOPFRA!$R$7:$R$56,MOPFRA!$P$7:$P$56,"") -> M | F51: =IFERROR(_xlfn.LET(_xlpm.lookup_result,_xlfn.XLOOKUP($C51,'دیده بان بازار'!$A$5:$A$3994,'دیده بان بازار'!F$5:F$3994),IF(ISERROR(_xlpm.lookup_result),V51,_xlpm.lookup_result)),V51) -> 4840 | G51: =IFERROR(_xlfn.LET(_xlpm.lookup_result,_xlfn.XLOOKUP($C51,'دیده بان بازار'!$A$5:$A$3994,'دیده بان بازار'!H$5:H$3994),IF(ISERROR(_xlpm.lookup_result),W51,_xlpm.lookup_result)),W51) -> 4980 | H51: =IFERROR(_xlfn.LET(_xlpm.lookup_result,_xlfn.XLOOKUP($C51,'دیده بان بازار'!$A$5:$A$3994,'دیده بان بازار'!K$5:K$3994),IF(ISERROR(_xlpm.lookup_result),X51,_xlpm.lookup_result)),X51) -> 4980 | I51: =IFERROR(_xlfn.LET(_xlpm.lookup_result,_xlfn.XLOOKUP($C51,'دیده بان بازار'!$A$5:$A$3994,'دیده بان بازار'!P$5:P$3994),IF(ISERROR(_xlpm.lookup_result),Y51,_xlpm.lookup_result)),Y51) -> 1065 | J51: =IFERROR(_xlfn.LET(_xlpm.lookup_result,_xlfn.XLOOKUP($C51,'دیده بان بازار'!$A$5:$A$3994,'دیده بان بازار'!Q$5:Q$3994),IF(ISERROR(_xlpm.lookup_result),Z51,_xlpm.lookup_result)),Z51) -> 4.68 | K51: =_xlfn.XLOOKUP(C51,MOPFRA!$R$7:$R$56,MOPFRA!$T$7:$T$56,"")/1000 -> 9.96 | L51: =_xlfn.XLOOKUP(C51,'MOPFRA Portfolio'!$P$8:$P$78,'MOPFRA Portfolio'!$AT$8:$AT$78,"") -> 500000 | M51: =_xlfn.XLOOKUP(C51,'MOPFRA Portfolio'!$P$8:$P$78,'MOPFRA Portfolio'!$AU$8:$AU$78,"") -> 246808.8 | O51: =IF(AND(Q51<0,R51<0,Q51<R51),Q51-R51,"") | P51: =IF(AND(Q51>=0,R51>=0,Q51>R51),Q51-R51,"") | Q51: =IFERROR(((K51-AA51)*100)/ABS($K$106),"") -> 0.15678749 | R51: =IFERROR((($AB51*$G51*0.9912*0.0001)-AC51)*100/ABS($AC$108),"") -> 0.654117 | S51: =IF(AND(R51>0,Q51>0,R51>Q51),R51-Q51,"") -> 0.49732951 | T51: =IF(AND(R51<0,Q51<0,R51<Q51),R51-Q51,"") | V51: 4700 | W51: 4840 | X51: 4840 | Y51: 1065 | Z51: 4.54 | AA51: 9.68 | AB51: 500000 | AC51: 239870.4
A52: =IFERROR(MATCH(C52,'دیده بان بازار'!$A$5:$A$3994,0 )+4,"Closed") -> Closed | B52: فولاد مباركه اصفهان | C52: فولاد | D52: =_xlfn.XLOOKUP(C52,MOPFRA!$R$7:$R$56,MOPFRA!$P$7:$P$56,"") -> M | F52: =IFERROR(_xlfn.LET(_xlpm.lookup_result,_xlfn.XLOOKUP($C52,'دیده بان بازار'!$A$5:$A$3994,'دیده بان بازار'!F$5:F$3994),IF(ISERROR(_xlpm.lookup_result),V52,_xlpm.lookup_result)),V52) -> 2604 | G52: =IFERROR(_xlfn.LET(_xlpm.lookup_result,_xlfn.XLOOKUP($C52,'دیده بان بازار'!$A$5:$A$3994,'دیده بان بازار'!H$5:H$3994),IF(ISERROR(_xlpm.lookup_result),W52,_xlpm.lookup_result)),W52) -> 2549 | H52: =IFERROR(_xlfn.LET(_xlpm.lookup_result,_xlfn.XLOOKUP($C52,'دیده بان بازار'!$A$5:$A$3994,'دیده بان بازار'!K$5:K$3994),IF(ISERROR(_xlpm.lookup_result),X52,_xlpm.lookup_result)),X52) -> 2549 | I52: =IFERROR(_xlfn.LET(_xlpm.lookup_result,_xlfn.XLOOKUP($C52,'دیده بان بازار'!$A$5:$A$3994,'دیده بان بازار'!P$5:P$3994),IF(ISERROR(_xlpm.lookup_result),Y52,_xlpm.lookup_result)),Y52) -> 518 | J52: =IFERROR(_xlfn.LET(_xlpm.lookup_result,_xlfn.XLOOKUP($C52,'دیده بان بازار'!$A$5:$A$3994,'دیده بان بازار'!Q$5:Q$3994),IF(ISERROR(_xlpm.lookup_result),Z52,_xlpm.lookup_result)),Z52) -> 5.03 | K52: =_xlfn.XLOOKUP(C52,MOPFRA!$R$7:$R$56,MOPFRA!$T$7:$T$56,"")/1000 -> 493.2315 | L52: =_xlfn.XLOOKUP(C52,'MOPFRA Portfolio'!$P$8:$P$78,'MOPFRA Portfolio'!$AT$8:$AT$78,"") -> 0 | M52: =_xlfn.XLOOKUP(C52,'MOPFRA Portfolio'!$P$8:$P$78,'MOPFRA Portfolio'!$AU$8:$AU$78,"") -> 0 | O52: =IF(AND(Q52<0,R52<0,Q52<R52),Q52-R52,"") | P52: =IF(AND(Q52>=0,R52>=0,Q52>R52),Q52-R52,"") | Q52: =IFERROR(((K52-AA52)*100)/ABS($K$106),"") -> 0 | R52: =IFERROR((($AB52*$G52*0.9912*0.0001)-AC52)*100/ABS($AC$108),"") -> 0 | S52: =IF(AND(R52>0,Q52>0,R52>Q52),R52-Q52,"") | T52: =IF(AND(R52<0,Q52<0,R52<Q52),R52-Q52,"") | V52: 2604 | W52: 2549 | X52: 2549 | Y52: 518 | Z52: 5.03 | AA52: 493.2315 | AB52: 0 | AC52: 0
A53: =IFERROR(MATCH(C53,'دیده بان بازار'!$A$5:$A$3994,0 )+4,"Closed") -> 2285 | B53: پارس فولاد سبزوار | C53: فسبزوار | D53: =_xlfn.XLOOKUP(C53,MOPFRA!$R$7:$R$56,MOPFRA!$P$7:$P$56,"") -> M | F53: =IFERROR(_xlfn.LET(_xlpm.lookup_result,_xlfn.XLOOKUP($C53,'دیده بان بازار'!$A$5:$A$3994,'دیده بان بازار'!F$5:F$3994),IF(ISERROR(_xlpm.lookup_result),V53,_xlpm.lookup_result)),V53) -> 65760 | G53: =IFERROR(_xlfn.LET(_xlpm.lookup_result,_xlfn.XLOOKUP($C53,'دیده بان بازار'!$A$5:$A$3994,'دیده بان بازار'!H$5:H$3994),IF(ISERROR(_xlpm.lookup_result),W53,_xlpm.lookup_result)),W53) -> 67730 | H53: =IFERROR(_xlfn.LET(_xlpm.lookup_result,_xlfn.XLOOKUP($C53,'دیده بان بازار'!$A$5:$A$3994,'دیده بان بازار'!K$5:K$3994),IF(ISERROR(_xlpm.lookup_result),X53,_xlpm.lookup_result)),X53) -> 67620 | I53: =IFERROR(_xlfn.LET(_xlpm.lookup_result,_xlfn.XLOOKUP($C53,'دیده بان بازار'!$A$5:$A$3994,'دیده بان بازار'!P$5:P$3994),IF(ISERROR(_xlpm.lookup_result),Y53,_xlpm.lookup_result)),Y53) -> 14832 | J53: =IFERROR(_xlfn.LET(_xlpm.lookup_result,_xlfn.XLOOKUP($C53,'دیده بان بازار'!$A$5:$A$3994,'دیده بان بازار'!Q$5:Q$3994),IF(ISERROR(_xlpm.lookup_result),Z53,_xlpm.lookup_result)),Z53) -> 4.56 | K53: =_xlfn.XLOOKUP(C53,MOPFRA!$R$7:$R$56,MOPFRA!$T$7:$T$56,"")/1000 -> 27.092 | L53: =_xlfn.XLOOKUP(C53,'MOPFRA Portfolio'!$P$8:$P$78,'MOPFRA Portfolio'!$AT$8:$AT$78,"") -> 45000 | M53: =_xlfn.XLOOKUP(C53,'MOPFRA Portfolio'!$P$8:$P$78,'MOPFRA Portfolio'!$AU$8:$AU$78,"") -> 302102.89 | O53: =IF(AND(Q53<0,R53<0,Q53<R53),Q53-R53,"") | P53: =IF(AND(Q53>=0,R53>=0,Q53>R53),Q53-R53,"") | Q53: =IFERROR(((K53-AA53)*100)/ABS($K$106),"") -> 0.36733069 | R53: =IFERROR((($AB53*$G53*0.9912*0.0001)-AC53)*100/ABS($AC$108),"") -> 0.68962621 | S53: =IF(AND(R53>0,Q53>0,R53>Q53),R53-Q53,"") -> 0.32229551 | T53: =IF(AND(R53<0,Q53<0,R53<Q53),R53-Q53,"") | V53: 64170 | W53: 66090 | X53: 65760 | Y53: 14832 | Z53: 4.43 | AA53: 26.436 | AB53: 45000 | AC53: 294787.84
A54: =IFERROR(MATCH(C54,'دیده بان بازار'!$A$5:$A$3994,0 )+4,"Closed") -> 1128 | B54: صبا فولاد خليج فارس | C54: فصبا | D54: =_xlfn.XLOOKUP(C54,MOPFRA!$R$7:$R$56,MOPFRA!$P$7:$P$56,"") -> M | F54: =IFERROR(_xlfn.LET(_xlpm.lookup_result,_xlfn.XLOOKUP($C54,'دیده بان بازار'!$A$5:$A$3994,'دیده بان بازار'!F$5:F$3994),IF(ISERROR(_xlpm.lookup_result),V54,_xlpm.lookup_result)),V54) -> 2714 | G54: =IFERROR(_xlfn.LET(_xlpm.lookup_result,_xlfn.XLOOKUP($C54,'دیده بان بازار'!$A$5:$A$3994,'دیده بان بازار'!H$5:H$3994),IF(ISERROR(_xlpm.lookup_result),W54,_xlpm.lookup_result)),W54) -> 2795 | H54: =IFERROR(_xlfn.LET(_xlpm.lookup_result,_xlfn.XLOOKUP($C54,'دیده بان بازار'!$A$5:$A$3994,'دیده بان بازار'!K$5:K$3994),IF(ISERROR(_xlpm.lookup_result),X54,_xlpm.lookup_result)),X54) -> 2795 | I54: =IFERROR(_xlfn.LET(_xlpm.lookup_result,_xlfn.XLOOKUP($C54,'دیده بان بازار'!$A$5:$A$3994,'دیده بان بازار'!P$5:P$3994),IF(ISERROR(_xlpm.lookup_result),Y54,_xlpm.lookup_result)),Y54) -> 158 | J54: =IFERROR(_xlfn.LET(_xlpm.lookup_result,_xlfn.XLOOKUP($C54,'دیده بان بازار'!$A$5:$A$3994,'دیده بان بازار'!Q$5:Q$3994),IF(ISERROR(_xlpm.lookup_result),Z54,_xlpm.lookup_result)),Z54) -> 17.69 | K54: =_xlfn.XLOOKUP(C54,MOPFRA!$R$7:$R$56,MOPFRA!$T$7:$T$56,"")/1000 -> 13.975 | L54: =_xlfn.XLOOKUP(C54,'MOPFRA Portfolio'!$P$8:$P$78,'MOPFRA Portfolio'!$AT$8:$AT$78,"") -> 2678001 | M54: =_xlfn.XLOOKUP(C54,'MOPFRA Portfolio'!$P$8:$P$78,'MOPFRA Portfolio'!$AU$8:$AU$78,"") -> 741914.47 | O54: =IF(AND(Q54<0,R54<0,Q54<R54),Q54-R54,"") | P54: =IF(AND(Q54>=0,R54>=0,Q54>R54),Q54-R54,"") | Q54: =IFERROR(((K54-AA54)*100)/ABS($K$106),"") -> 0.21838258 | R54: =IFERROR((($AB54*$G54*0.9912*0.0001)-AC54)*100/ABS($AC$108),"") -> 1.9519232 | S54: =IF(AND(R54>0,Q54>0,R54>Q54),R54-Q54,"") -> 1.7335407 | T54: =IF(AND(R54<0,Q54<0,R54<Q54),R54-Q54,"") | V54: 2638 | W54: 2717 | X54: 2714 | Y54: 158 | Z54: 17.18 | AA54: 13.585 | AB54: 2678001 | AC54: 721209.88
